File: QuDAP/Example_1
Moment (emu)
nan
-3.17819561380995e-05
-3.0587943858549e-05
-3.24600472477377e-05
-3.25716037557306e-05
-3.08597892791796e-05
-3.05041755272959e-05
-3.15716160674241e-05
-3.19381999107799e-05
-3.14580650916405e-05
-3.09878630763387e-05
-3.05643896867494e-05
-3.16768289237492e-05
-3.16121917314484e-05
-3.1099386179707e-05
-3.17806427668867e-05
-3.06692633446901e-05
-3.09601934400863e-05
-3.27015720134183e-05
-3.15711180035716e-05
-3.24252197314976e-05
-3.15040672999072e-05
-3.15622682123154e-05
-3.16056827897671e-05
-3.12362307426815e-05
-3.04353737175336e-05
-3.12151927323592e-05
-3.24189337788233e-05
-3.01760901844141e-05
-3.08005463681217e-05
-3.11118923136061e-05
-3.12751659202266e-05
-3.11979521477902e-05
-3.11425634831995e-05
-3.1919812935562e-05
-3.17954316719594e-05
-3.11686368324452e-05
-3.16813110348885e-05
-3.04393601426954e-05
-3.09968550773807e-05
-3.09942986205423e-05
-3.1406291405736e-05
-3.21309885099748e-05
-3.09718919370345e-05
-3.10370675294236e-05
-3.14749092187018e-05
-3.16874192511119e-05
-3.25357020697496e-05
-3.12976105835639e-05
-3.09044041291922e-05
-3.21233229395428e-05
-3.14699815347793e-05
-3.13873173749127e-05
-3.1024894871165e-05
-3.11795846342008e-05
-3.12781914918957e-05
-3.08823528511096e-05
-3.17332331667163e-05
-3.14100004902706e-05
-3.09521378482315e-05
-3.08221156963681e-05
-3.05975684834122e-05
-3.15255299944594e-05
-3.03448781341164e-05
-2.96315162398801e-05
-3.06133548337273e-05
-3.16824101748956e-05
-3.10520997355587e-05
-3.13457775879374e-05
-3.14273801502151e-05
-3.06747841529755e-05
-3.13195425575204e-05
-3.15080516256433e-05
-3.015922811828e-05
-3.1320929158493e-05
-3.11694352732166e-05
-3.09789468963315e-05
-3.14246968477264e-05
-3.07874486752654e-05
-3.04584351309343e-05
-3.19698907623707e-05
-3.10317343851793e-05
-3.03491529719271e-05
-3.03678638053441e-05
-3.08455467412386e-05
-3.10546090214754e-05
-3.09553967131378e-05
-3.17706156590492e-05
-3.15568696838544e-05
-2.99216112409407e-05
-3.14319487224723e-05
-3.08231965664992e-05
-3.02570645959847e-05
-3.08845059643678e-05
-3.0642766452918e-05
-3.0586946947971e-05
-3.03977653899952e-05
-3.01743982938399e-05
-3.07520315650144e-05
-3.19882176286612e-05
-3.12355339188717e-05
-3.08086271156918e-05
-2.94938539133036e-05
-3.14355587504548e-05
-3.05084232907857e-05
-3.04616404063432e-05
-3.048088201927e-05
-3.06461799185449e-05
-3.09114726925189e-05
-3.15688999389381e-05
-3.14901937910375e-05
-3.10506729324229e-05
-3.09279379917602e-05
-3.08731701337577e-05
-3.12409420116224e-05
-2.97228665421136e-05
-2.95086094564753e-05
-3.06665781523403e-05
-3.11676199121446e-05
-3.16101412957994e-05
-3.10335031982094e-05
-2.91571945129712e-05
-3.07041407541766e-05
-3.13344538067686e-05
-2.95364035272095e-05
-3.15112301860367e-05
-3.1323510688789e-05
-2.98356376893025e-05
-3.00634124407439e-05
-3.06064727975962e-05
-3.01962695012402e-05
-3.00011923731661e-05
-2.96738295729376e-05
-3.07530499986163e-05
-3.13121038105443e-05
-3.1139361344629e-05
-3.06091689815879e-05
-3.04119493062031e-05
-2.92336332354926e-05
-3.07028342129978e-05
-2.96118963719576e-05
-3.09485656558688e-05
-2.979739165858e-05
-3.03124106353945e-05
-3.14199775426715e-05
-3.13228373090885e-05
-2.95758033469812e-05
-2.94071301525352e-05
-3.01159790703365e-05
-2.96635965000572e-05
-2.94769979204268e-05
-3.00951212447482e-05
-3.03370180867054e-05
-3.07029273229884e-05
-3.01071812626359e-05
-3.05239016860468e-05
-3.10823470804751e-05
-2.92856292484986e-05
-2.95859702074618e-05
-3.01661795271161e-05
-2.96510217008859e-05
-3.08016952579281e-05
-2.94919513127584e-05
-3.04427710451883e-05
-3.0581937679652e-05
-2.94766780607355e-05
-3.07325935610326e-05
-3.13515532302309e-05
-3.04790747752011e-05
-3.0065986172999e-05
-3.01115440058318e-05
-3.05074765190028e-05
-2.97564373635152e-05
-2.97956718002153e-05
-3.13826064538111e-05
-3.00884330597188e-05
-2.90467712409719e-05
-2.92170427948436e-05
-2.9548919756266e-05
-2.96869720425186e-05
-2.9843812415508e-05
-2.91821480906653e-05
-2.99503035912204e-05
-3.04600123235108e-05
-3.08337844456092e-05
-3.03510268369127e-05
-2.93306432307611e-05
-2.95975992175058e-05
-3.01608800739005e-05
-2.86201605560059e-05
-3.01715148216599e-05
-2.99073785664018e-05
-3.00764388396021e-05
-3.03570092841449e-05
-2.97880842047628e-05
-2.94649279661582e-05
-2.94869458803793e-05
-3.0285449595832e-05
-2.93954705608706e-05
-2.89739222312185e-05
-2.92061753731444e-05
-2.94101169537635e-05
-2.98621420692614e-05
-3.01441623115369e-05
-2.91900952248559e-05
-2.81206062498216e-05
-2.88151993881753e-05
-3.00901743293806e-05
-2.95669240835005e-05
-2.97145154304461e-05
-2.90742033739664e-05
-2.90664905325852e-05
-3.00560813676095e-05
-3.00258853997695e-05
-3.02738270853993e-05
-2.97441725080133e-05
-2.8668584439833e-05
-3.00337968045732e-05
-2.9296173537144e-05
-3.02867016797269e-05
-2.87422762782481e-05
-3.07251593089467e-05
-3.02321425390099e-05
-3.04132708652136e-05
-3.04448861529399e-05
-2.89330980276005e-05
-3.07250999105443e-05
-3.0283962147953e-05
-2.9741848646702e-05
-2.86647226692192e-05
-2.80103256309691e-05
-3.04150936648444e-05
-3.0865574231466e-05
-2.96903918219125e-05
-3.11074112598954e-05
-2.96201019258352e-05
-3.03399170337668e-05
-3.06571935487167e-05
-3.03608450719345e-05
-2.96641421035655e-05
-3.09475577815489e-05
-3.09299706948393e-05
-2.84319654951367e-05
-3.01638292299102e-05
-3.02237787697417e-05
-3.03075696825344e-05
-2.83574249051683e-05
-2.98969849644188e-05
-2.89671774797335e-05
-3.04794822762606e-05
-2.99940703762444e-05
-2.88633675348079e-05
-3.06700459938901e-05
-2.98253094256153e-05
-2.95177578298952e-05
-2.86654227445653e-05
-3.1265663112225e-05
-2.86765947115268e-05
-2.95438843641184e-05
-2.95261271931728e-05
-2.92976935647758e-05
-3.02392309757594e-05
-2.89784507806752e-05
-3.00952933186271e-05
-2.95291130998946e-05
-2.91901213901061e-05
-2.92262266289938e-05
-2.93365054039899e-05
-2.84361740722392e-05
-2.87003168317448e-05
-2.93148513685033e-05
-3.02231487527491e-05
-3.03070648580451e-05
-2.96210906958687e-05
-2.82162050462147e-05
-2.96177364278618e-05
-2.98537962792817e-05
-2.87735944138716e-05
-3.01328710768633e-05
-3.00002155095832e-05
-2.89673199779916e-05
-2.98873202163704e-05
-2.83841588068747e-05
-3.00041567614853e-05
-2.95978371402128e-05
-2.86621823986329e-05
-2.97011576590883e-05
-3.04134140100964e-05
-2.87852616120716e-05
-3.0184315359596e-05
-2.95452891837027e-05
-2.83256965390501e-05
-2.92543050651371e-05
-3.01826700053157e-05
-2.86997359394722e-05
-2.83437403676572e-05
-2.89985736515613e-05
-2.88191497748643e-05
-3.00990667578837e-05
-2.85762784643059e-05
-2.88650744234646e-05
-2.80839080577548e-05
-2.983977825918e-05
-2.89047499891334e-05
-2.90348492770953e-05
-2.89901187522786e-05
-3.01941583492066e-05
-2.91299212999845e-05
-2.87416800231886e-05
-3.14288376066546e-05
-2.92971347994282e-05
-2.82458576934464e-05
-2.89779212169533e-05
-2.86459166329205e-05
-2.97385340960016e-05
-2.76817578695179e-05
-2.97892811913166e-05
-2.80699833109811e-05
-2.71433180814861e-05
-2.85271209864615e-05
-2.91015041890655e-05
-2.83394885375809e-05
-2.89184416579137e-05
-2.83954934730939e-05
-2.84017886404683e-05
-2.93100770300851e-05
-2.97351458760725e-05
-2.91489022367961e-05
-2.76445012706627e-05
-2.92643754836558e-05
-2.89420439094819e-05
-2.93197436588455e-05
-2.96730150246833e-05
-2.91917180841819e-05
-2.74386061282828e-05
-2.8375755093329e-05
-2.84758785244334e-05
-2.89847539329342e-05
-2.74533178088934e-05
-2.96215713723045e-05
-2.93213557388558e-05
-2.93516099206766e-05
-2.82698468563706e-05
-2.83032558791286e-05
-2.85082949336036e-05
-2.73053111539634e-05
-2.86880074439702e-05
-2.77179255767083e-05
-2.86162244377019e-05
-2.93058889950532e-05
-2.88136870650737e-05
-2.86191521665518e-05
-2.85167504253265e-05
-2.8571631994306e-05
-2.92626125177976e-05
-2.83852621150474e-05
-2.77131365730295e-05
-2.87823897577432e-05
-2.810808389804e-05
-2.97501408398107e-05
-2.86363783144232e-05
-2.70445426449166e-05
-2.80624425318277e-05
-2.96296794108011e-05
-2.83913262480085e-05
-2.95264242766398e-05
-2.76309841877396e-05
-2.91816854216527e-05
-2.88133094236089e-05
-2.93949139551954e-05
-2.82801711327721e-05
-2.81550511340403e-05
-2.82671127102791e-05
-2.94436520127668e-05
-2.82746548211458e-05
-2.87227072961666e-05
-2.80122654373216e-05
-2.7722576121024e-05
-2.76310198159343e-05
-2.79316379669788e-05
-2.83539566371675e-05
-2.95022517033076e-05
-2.80862629309201e-05
-2.73188433661112e-05
-2.82830623906585e-05
-2.89900796429381e-05
-2.72147784463722e-05
-2.81681727020722e-05
-2.7340552345247e-05
-2.85732682015516e-05
-2.91476822470125e-05
-2.84916812879379e-05
-2.86277164541397e-05
-2.76875550010983e-05
-2.73137369314836e-05
-2.76431558437941e-05
-2.73393447839576e-05
-2.81749902355548e-05
-2.77274522597752e-05
-2.86803973881995e-05
-2.82987856051177e-05
-2.79467580167688e-05
-2.84713511897916e-05
-2.87382324890521e-05
-2.87265596717749e-05
-2.81656666148164e-05
-2.75815513465004e-05
-2.92609143058585e-05
-2.90037709502147e-05
-2.74646046205425e-05
-2.81415859463881e-05
-2.77083990776161e-05
-2.79546248284477e-05
-2.82742704419997e-05
-2.80938794644447e-05
-2.90537863852525e-05
-2.8000761299685e-05
-2.78163868490958e-05
-2.86733589846633e-05
-2.85998313922592e-05
-2.72382180799784e-05
-2.81929844659495e-05
-2.79626395405435e-05
-2.7541989654287e-05
-2.65048461702109e-05
-2.7930162826903e-05
-2.78005531286695e-05
-2.56472192565657e-05
-2.69571727855572e-05
-2.77335179944941e-05
-2.79165473694384e-05
-2.61489394237099e-05
-2.73397127625176e-05
-2.80689353001384e-05
-2.75056272524468e-05
-2.76038665589289e-05
-2.86566793487342e-05
-2.79636890114311e-05
-2.72256237807912e-05
-2.78122339435136e-05
-2.92517876959224e-05
-2.7880438803849e-05
-2.82426298907704e-05
-2.78831530666962e-05
-2.69084400228417e-05
-2.74178030849835e-05
-2.73896546565207e-05
-2.77313168867824e-05
-2.89915205430141e-05
-2.7697986755224e-05
-2.80071564746206e-05
-2.78564819298057e-05
-2.7995843845656e-05
-2.67725538962384e-05
-2.65461071546054e-05
-2.69767567889573e-05
-2.68727775569339e-05
-2.67425456661641e-05
-2.75736566886017e-05
-2.92764182372581e-05
-2.72681059196242e-05
-2.71056516886158e-05
-2.75040393760872e-05
-2.81450822987344e-05
-2.76940370697135e-05
-2.74490622988554e-05
-2.75014381252991e-05
-2.66326516038537e-05
-2.75877436859097e-05
-2.71093163616627e-05
-2.70298133173497e-05
-2.75021829253631e-05
-2.77709938485911e-05
-2.82281516955099e-05
-2.76743422025224e-05
-2.88878592056536e-05
-2.66802515388187e-05
-2.72145990637405e-05
-2.61096870963199e-05
-2.84760544704246e-05
-2.70411864896969e-05
-2.68620776949453e-05
-2.75073051032574e-05
-2.84140820162484e-05
-2.78846770554118e-05
-2.76600722277929e-05
-2.86747902605166e-05
-2.79260324204999e-05
-2.7919082025257e-05
-2.85097326316131e-05
-2.70305594720635e-05
-2.65018827091666e-05
-2.71947420152587e-05
-2.71013375402714e-05
-2.80238325928193e-05
-2.74047384379804e-05
-2.67051769286205e-05
-2.69343053869489e-05
-2.79234987967629e-05
-2.63653685205707e-05
-2.79789287434307e-05
-2.47850743974162e-05
-2.69355204101574e-05
-2.72904511916444e-05
-2.8037961542641e-05
-2.64991561411035e-05
-2.67097807102543e-05
-2.73505128146128e-05
-2.65728790401108e-05
-2.59044205364329e-05
-2.77572198495926e-05
-2.74915326252321e-05
-2.69347381117043e-05
-2.66973145783765e-05
-2.72992173040562e-05
-2.62184520284316e-05
-2.80099375764388e-05
-2.72189231484181e-05
-2.72303218650211e-05
-2.63484599038626e-05
-2.65852953159513e-05
-2.68453424700803e-05
-2.71597543411495e-05
-2.86279105786189e-05
-2.77743506764501e-05
-2.74703277728341e-05
-2.76840848838561e-05
-2.69633940751881e-05
-2.65424472069708e-05
-2.76317385822167e-05
-2.7040375102035e-05
-2.64771209680547e-05
-2.66924237434768e-05
-2.66729251186953e-05
-2.72506695814609e-05
-2.77727743316457e-05
-2.75915634516239e-05
-2.6546475712841e-05
-2.78258626405214e-05
-2.79095509109306e-05
-2.64971198967623e-05
-2.66392086921727e-05
-2.76969188195456e-05
-2.62045777054583e-05
-2.70739476047294e-05
-2.66957606883909e-05
-2.74273395275238e-05
-2.62982055461628e-05
-2.57380656870219e-05
-2.63674959636752e-05
-2.63268205169616e-05
-2.8307348355403e-05
-2.68336941973327e-05
-2.80323378335719e-05
-2.67348026675192e-05
-2.70200746648267e-05
-2.69426529358123e-05
-2.66274992059175e-05
-2.69341517496303e-05
-2.65220605992555e-05
-2.78568640795713e-05
-2.65921545611302e-05
-2.62149463278091e-05
-2.6679739826786e-05
-2.67302581974011e-05
-2.64821247293077e-05
-2.6723708547572e-05
-2.67335775754918e-05
-2.5875741969994e-05
-2.75037503344547e-05
-2.6511217278157e-05
-2.62040963924578e-05
-2.63094085789183e-05
-2.56822548830696e-05
-2.5984339416363e-05
-2.72532778718963e-05
-2.66332653625434e-05
-2.69246609570625e-05
-2.71035231725598e-05
-2.61869160101835e-05
-2.71824754383058e-05
-2.60745270886774e-05
-2.70968837095652e-05
-2.63882478968462e-05
-2.69130287074372e-05
-2.68249238906134e-05
-2.63993617747581e-05
-2.66132947690872e-05
-2.69617477709512e-05
-2.680462275956e-05
-2.674064064762e-05
-2.52912547307338e-05
-2.60685454035185e-05
-2.74504104420218e-05
-2.66950516329112e-05
-2.66829552795957e-05
-2.62319252058495e-05
-2.64028739596976e-05
-2.75442878166299e-05
-2.72705247865117e-05
-2.73843704047702e-05
-2.60869173080357e-05
-2.69471009420277e-05
-2.63262097486253e-05
-2.67954959397115e-05
-2.61062468575464e-05
-2.56134173744953e-05
-2.7056603251611e-05
-2.63282619744393e-05
-2.77563761693772e-05
-2.63178708247542e-05
-2.50073142776744e-05
-2.74896443703689e-05
-2.69286742225685e-05
-2.77816825406438e-05
-2.66512049617563e-05
-2.51124080578798e-05
-2.6350465323657e-05
-2.7531593286371e-05
-2.7291990868097e-05
-2.55865353155472e-05
-2.65945071667578e-05
-2.74008939478255e-05
-2.66181512295273e-05
-2.56794460662589e-05
-2.74196904843942e-05
-2.58416309170253e-05
-2.54402024390194e-05
-2.64892471013088e-05
-2.60503027999522e-05
-2.59154489647374e-05
-2.68879943601918e-05
-2.6829836548687e-05
-2.54362555803568e-05
-2.60945093338564e-05
-2.59804708289147e-05
-2.56257962158429e-05
-2.73751326424926e-05
-2.58229941990426e-05
-2.52666030447751e-05
-2.72851910258105e-05
-2.79432005191058e-05
-2.6139807527559e-05
-2.61438861254551e-05
-2.63150262239249e-05
-2.68218307627864e-05
-2.6371882380843e-05
-2.71461692476105e-05
-2.49552806270133e-05
-2.64389575683498e-05
-2.71442819312601e-05
-2.63627939017192e-05
-2.69445173954956e-05
-2.70152994853137e-05
-2.62431155595574e-05
-2.61893486400467e-05
-2.59072576078217e-05
-2.53102341729163e-05
-2.59344463800935e-05
-2.57234918142878e-05
-2.62038880067098e-05
-2.60355114561978e-05
-2.75593776358134e-05
-2.71484343231588e-05
-2.60932509818158e-05
-2.5595320086887e-05
-2.67072132391966e-05
-2.66188611789093e-05
-2.67360255255515e-05
-2.64850233505874e-05
-2.52480844555932e-05
-2.60594194744656e-05
-2.63756782425041e-05
-2.42653012783165e-05
-2.63884249907762e-05
-2.62245638725618e-05
-2.61465287826797e-05
-2.50256750600956e-05
-2.50508631698493e-05
-2.73013396101984e-05
-2.65573002708923e-05
-2.60517072541103e-05
-2.71037565703878e-05
-2.6183254522893e-05
-2.62392174846329e-05
-2.63287893343203e-05
-2.69361097116603e-05
-2.59081964261192e-05
-2.60122993463727e-05
-2.52610714702894e-05
-2.69379307654608e-05
-2.56214690809883e-05
-2.64910966760511e-05
-2.63306071300271e-05
-2.53461712021357e-05
-2.54681846304947e-05
-2.63131946795591e-05
-2.54906510218804e-05
-2.59419965512477e-05
-2.50348012479221e-05
-2.67058724060555e-05
-2.4123597869142e-05
-2.65624412733401e-05
-2.58117089922758e-05
-2.64330687403579e-05
-2.51075940859639e-05
-2.53071100724722e-05
-2.70018266949069e-05
-2.61634100574638e-05
-2.5776136152719e-05
-2.58379312602535e-05
-2.5198529004256e-05
-2.57525829159352e-05
-2.55380727454116e-05
-2.54643385014068e-05
-2.52300863338955e-05
-2.50583330195365e-05
-2.52574157304423e-05
-2.49131437780708e-05
-2.55405039192123e-05
-2.6465316971645e-05
-2.50179251907048e-05
-2.49333638391217e-05
-2.49772055671226e-05
-2.59808598545571e-05
-2.5384352357765e-05
-2.50276368518657e-05
-2.45024877294076e-05
-2.57696780337669e-05
-2.5037967404259e-05
-2.48247025630238e-05
-2.61505229947198e-05
-2.60148246076793e-05
-2.5897002667746e-05
-2.47666356946319e-05
-2.54197092200748e-05
-2.63476098130517e-05
-2.57547973449493e-05
-2.50420224934358e-05
-2.57307425115121e-05
-2.57221859600558e-05
-2.47681481287774e-05
-2.41012261851154e-05
-2.55924497798534e-05
-2.53079220461434e-05
-2.55464557080348e-05
-2.48415252852476e-05
-2.50397649957365e-05
-2.56139603847092e-05
-2.51277070329358e-05
-2.61874512304924e-05
-2.64376062721518e-05
-2.5703370764989e-05
-2.59804026039262e-05
-2.47832598637695e-05
-2.60530767299822e-05
-2.48356137152955e-05
-2.56595569563151e-05
-2.42249930494233e-05
-2.4265385779335e-05
-2.48875006906284e-05
-2.46068404108147e-05
-2.49000426069048e-05
-2.37560611862026e-05
-2.54066108607036e-05
-2.4955977764425e-05
-2.47158124012304e-05
-2.5875124426947e-05
-2.54396363355599e-05
-2.59528360278131e-05
-2.55759831882324e-05
-2.5161971710027e-05
-2.53517049211064e-05
-2.55179015630832e-05
-2.51531140080579e-05
-2.51626558452292e-05
-2.53192887517759e-05
-2.45765987737723e-05
-2.64808110205637e-05
-2.47809515899948e-05
-2.51687449898177e-05
-2.51996402174456e-05
-2.63294630108492e-05
-2.39511072267642e-05
-2.55476942147954e-05
-2.52043710285972e-05
-2.49254690389007e-05
-2.629138818762e-05
-2.45785429371909e-05
-2.53029935298441e-05
-2.47771612000966e-05
-2.6161633758514e-05
-2.51676209299529e-05
-2.52333872852078e-05
-2.58793092981597e-05
-2.56411323068615e-05
-2.51539277228161e-05
-2.50018082755597e-05
-2.5453184474894e-05
-2.48289590864022e-05
-2.47298738099095e-05
-2.4089357351507e-05
-2.42498281318226e-05
-2.5337008357227e-05
-2.47154198910264e-05
-2.49108163369351e-05
-2.49752932572246e-05
-2.49233180684254e-05
-2.50011018601062e-05
-2.29516797536123e-05
-2.57386256948351e-05
-2.54189478894703e-05
-2.44022257105736e-05
-2.40056227875686e-05
-2.53020722743884e-05
-2.52579512733088e-05
-2.62674125660249e-05
-2.50992485484779e-05
-2.48991887986852e-05
-2.48301744257945e-05
-2.50805355314922e-05
-2.38895958641119e-05
-2.56335134646978e-05
-2.45838160635589e-05
-2.42559458160133e-05
-2.45035058490331e-05
-2.42251960446641e-05
-2.48111129957011e-05
-2.30679455152141e-05
-2.49623908807773e-05
-2.4967392210193e-05
-2.5658742563048e-05
-2.5363029362478e-05
-2.48137748559514e-05
-2.42849397412588e-05
-2.51865436598414e-05
-2.47426215488061e-05
-2.49598253163688e-05
-2.4579538186069e-05
-2.52109952020429e-05
-2.54401454544502e-05
-2.40799855644141e-05
-2.57563202074726e-05
-2.41856977330014e-05
-2.42844515535208e-05
-2.44053972969444e-05
-2.52443174850065e-05
-2.42059231589422e-05
-2.51293746960529e-05
-2.35252359960894e-05
-2.34185983256225e-05
-2.41531999172129e-05
-2.54771910132291e-05
-2.40610277680903e-05
-2.26988506673688e-05
-2.51784938187503e-05
-2.44039852359498e-05
-2.44975021567056e-05
-2.3977164048277e-05
-2.35802019499993e-05
-2.35047772969549e-05
-2.56151620918209e-05
-2.49250516759971e-05
-2.43676990995707e-05
-2.4480015650935e-05
-2.45607821686855e-05
-2.58662392320001e-05
-2.44177953497397e-05
-2.45361157462583e-05
-2.42470397180961e-05
-2.37148455267341e-05
-2.45767397492806e-05
-2.3774254070507e-05
-2.45809760594659e-05
-2.54994934369871e-05
-2.43344945611267e-05
-2.52292561764961e-05
-2.42687825844527e-05
-2.42248041369847e-05
-2.39423666180063e-05
-2.33137552387668e-05
-2.40558625384157e-05
-2.448092713567e-05
-2.48605017649576e-05
-2.50941895116548e-05
-2.30362715996052e-05
-2.36015164810826e-05
-2.31510524723118e-05
-2.50278184694071e-05
-2.34992255787836e-05
-2.39143264687669e-05
-2.50098166924228e-05
-2.4002422472842e-05
-2.44123895217223e-05
-2.52664789856133e-05
-2.3704859865692e-05
-2.45765765560385e-05
-2.38356065018389e-05
-2.4799043380581e-05
-2.56878536407951e-05
-2.44322320694385e-05
-2.42793864955415e-05
-2.322291771736e-05
-2.46999092655979e-05
-2.3241776932684e-05
-2.38528473214722e-05
-2.45875650655924e-05
-2.42312743341308e-05
-2.43669245029173e-05
-2.42496954670674e-05
-2.3145706514327e-05
-2.34258383927396e-05
-2.4338919399107e-05
-2.42528068590496e-05
-2.4653606065441e-05
-2.37871801442943e-05
-2.33340317569754e-05
-2.42345621921116e-05
-2.39988236184623e-05
-2.4794127239985e-05
-2.43695971800113e-05
-2.45400063029654e-05
-2.41008830247179e-05
-2.34100479160473e-05
-2.3760553080713e-05
-2.36663851033063e-05
-2.37488508868786e-05
-2.34339111827832e-05
-2.45644204468224e-05
-2.40757704081822e-05
-2.38089462972867e-05
-2.47513502928897e-05
-2.39223771461046e-05
-2.3936323844277e-05
-2.44457052527489e-05
-2.40518793952241e-05
-2.34348813566458e-05
-2.39534240659864e-05
-2.33833099626025e-05
-2.41147183303622e-05
-2.27577317901586e-05
-2.45760584046579e-05
-2.33665832003265e-05
-2.46268648800929e-05
-2.29159732592036e-05
-2.31327449392511e-05
-2.32963303562283e-05
-2.30202364301475e-05
-2.28997455796743e-05
-2.20686491328004e-05
-2.35793585510993e-05
-2.47108288128152e-05
-2.13786552755441e-05
-2.33312539939714e-05
-2.32384784642651e-05
-2.37442039746083e-05
-2.33432683986424e-05
-2.33186354593749e-05
-2.25416210348143e-05
-2.43154966173565e-05
-2.43301719991408e-05
-2.34149066320401e-05
-2.3534176616597e-05
-2.31961118718032e-05
-2.3021622412327e-05
-2.31849512999739e-05
-2.32883636790019e-05
-2.26457760416436e-05
-2.24145785020668e-05
-2.37577875061243e-05
-2.34244379310812e-05
-2.36260234478445e-05
-2.23570704908216e-05
-2.32589900638968e-05
-2.33020830025283e-05
-2.16928062701552e-05
-2.35941963655653e-05
-2.34074478771034e-05
-2.29692633158812e-05
-2.44306348383063e-05
-2.37501141254749e-05
-2.34766917704181e-05
-2.4012148113593e-05
-2.32928392780982e-05
-2.30229780835797e-05
-2.37903505641109e-05
-2.41258219613246e-05
-2.18882156119143e-05
-2.26790709873112e-05
-2.26540385851506e-05
-2.24991653474096e-05
-2.35422042990197e-05
-2.27720412208684e-05
-2.26114150157764e-05
-2.25299494571939e-05
-2.19759789869297e-05
-2.24554327326417e-05
-2.35835550716738e-05
-2.20973828607847e-05
-2.37393924510333e-05
-2.26162834612299e-05
-2.24617813347484e-05
-2.32901634141765e-05
-2.31267778033968e-05
-2.20155535215209e-05
-2.42009920581907e-05
-2.27754727731332e-05
-2.16815765256088e-05
-2.29887119411786e-05
-2.29626390686451e-05
-2.22202054097894e-05
-2.23753367565046e-05
-2.3460428251369e-05
-2.35237458149427e-05
-2.39752112168165e-05
-2.35829559694049e-05
-2.35775169423617e-05
-2.29259315378081e-05
-2.34317742564034e-05
-2.24774448503578e-05
-2.24153583256566e-05
-2.31936603618073e-05
-2.34392782954905e-05
-2.28848911839837e-05
-2.27192247371602e-05
-2.2949184257613e-05
-2.33786936517282e-05
-2.28412300854133e-05
-2.26148845830223e-05
-2.29388681986842e-05
-2.20561154597007e-05
-2.26125542325321e-05
-2.30406042728475e-05
-2.24004389968105e-05
-2.21379067226113e-05
-2.31362911298058e-05
-2.26207224052556e-05
-2.33295086530927e-05
-2.33043472861637e-05
-2.32619891560254e-05
-2.1800424641305e-05
-2.3094833728864e-05
-2.35348657780674e-05
-2.25095767139645e-05
-2.24937746268803e-05
-2.17312909372081e-05
-2.30831704277268e-05
-2.30946128263877e-05
-2.32517435207245e-05
-2.25138364247359e-05
-2.09647690470841e-05
-2.30570412018513e-05
-2.32242064806611e-05
-2.27489366081313e-05
-2.15188764879356e-05
-2.16206580282046e-05
-2.38261916953442e-05
-2.18059531050925e-05
nan
-2.39005262016135e-05
-2.24727967793591e-05
-2.19648912090689e-05
-2.17622510093817e-05
-2.26328161535678e-05
-2.14130481077249e-05
-2.19626396552437e-05
-2.27715857165895e-05
-2.04204576073579e-05
-2.30283370286303e-05
-2.294234814523e-05
-2.15317702063137e-05
-2.13122876668718e-05
-2.26792950787883e-05
-2.21515186526781e-05
-2.08914834864223e-05
-2.15220853485775e-05
-2.1740513299802e-05
-2.26208104806754e-05
-2.20594137513155e-05
-2.2836719229619e-05
-2.23150870306651e-05
-2.18340948206597e-05
-2.17554828306939e-05
-2.22379213526491e-05
-2.11922934087315e-05
-2.27196901682231e-05
-2.26134375768661e-05
-2.37869215601958e-05
-2.1754573292686e-05
-2.10295073133503e-05
-2.13662309078162e-05
-2.25780516162041e-05
-2.09301013207246e-05
-2.30724025119472e-05
-2.23652709482024e-05
-2.08517698085538e-05
-2.17591029400582e-05
-2.25229520419246e-05
-2.17890916225835e-05
-2.26469277900257e-05
-2.22658570461135e-05
-2.07934792971631e-05
-2.13047567752771e-05
-2.27704834763779e-05
-2.21619475200757e-05
-2.24903415717488e-05
-2.08864985719515e-05
-2.14922113808304e-05
-2.32032282838041e-05
-2.15266071136343e-05
-2.12575088183732e-05
-2.24399286738464e-05
-2.04262279541429e-05
-2.14972251426244e-05
-2.13772436513281e-05
-2.17808479255165e-05
-2.20580688150547e-05
-2.10649481019037e-05
-2.09200472213479e-05
-2.07900127549259e-05
-2.24420462539143e-05
-2.27068479409136e-05
-2.02562260309907e-05
-2.20731960681307e-05
-2.12121339582576e-05
-2.0685387588303e-05
-2.24329764688684e-05
-2.22998215837128e-05
-2.23854922671116e-05
-2.21638961428967e-05
-2.19752869873049e-05
-2.20717978545998e-05
-2.19334271827671e-05
-2.02034327763448e-05
-2.10625354891844e-05
-2.16961129063561e-05
-2.14591965624582e-05
-2.22751809306045e-05
-2.22494098537476e-05
-2.11752620907582e-05
-2.15919911954319e-05
-2.02932688224482e-05
-2.19914813729592e-05
-2.07195754076178e-05
-2.20561203793909e-05
-2.12547705175582e-05
-2.22088912927536e-05
-2.16828136391886e-05
-2.11074024950581e-05
-2.28108935310749e-05
-2.15269950255932e-05
-2.08576973722503e-05
-2.28497737099092e-05
-2.13834640033511e-05
-2.23317870014181e-05
-2.11286098902842e-05
-2.16821410971625e-05
-2.1283201043841e-05
-2.11272801951127e-05
-2.20284399328469e-05
-2.16988099153812e-05
-2.04401465499761e-05
-2.18068708994204e-05
-2.19063287995107e-05
-2.13498009410271e-05
-2.19228145252775e-05
-2.20169194408394e-05
-2.13102821766664e-05
-2.11431891747429e-05
-2.15404364273716e-05
-2.19242340787107e-05
-2.13146066244073e-05
-2.13720810998994e-05
-2.12101022846635e-05
-2.1685606558104e-05
-2.02153082836511e-05
-2.17182815121202e-05
-2.19097423340445e-05
-2.09363104590948e-05
-2.2248925072859e-05
-2.09409023831066e-05
-2.07815709610831e-05
-2.14444949803312e-05
-2.09878528546239e-05
-2.09362552051083e-05
-2.18612108019275e-05
-2.05142938217604e-05
-2.12126674634293e-05
-2.15621946932229e-05
-2.11629388283091e-05
-2.26840154875623e-05
-2.09404776592453e-05
-2.14559845950394e-05
-2.22264238302104e-05
-2.05299273682015e-05
-2.10582398115153e-05
-2.19455614135275e-05
-2.12029231762578e-05
-2.12978986880889e-05
-2.04367982467052e-05
-2.1371831433058e-05
-2.12008690847538e-05
-2.14994225131475e-05
-2.0890358246908e-05
-2.02591458436347e-05
-2.03380172601825e-05
-2.14834902575762e-05
-2.25216492447827e-05
-2.1701930002703e-05
-2.19963247873366e-05
-2.06125830774739e-05
-2.1382223449293e-05
-2.15372935999489e-05
-2.09682105048889e-05
-2.0120891731203e-05
-2.21930355491587e-05
-2.11235037214678e-05
-2.16494659790156e-05
-2.10382361949835e-05
-2.05566397392044e-05
-2.10037772752428e-05
-2.17162685204992e-05
-2.14813619612702e-05
-2.11766550296643e-05
-1.93116469162409e-05
-1.99999684558879e-05
-2.02777066283267e-05
-2.14503704568915e-05
-2.05723383130404e-05
-2.10938887739976e-05
-2.15238239828511e-05
-2.14756875069809e-05
-2.11185985004237e-05
-2.03176940511764e-05
-2.11833689323201e-05
-2.11887158532067e-05
-1.96869705232659e-05
-2.16836032012434e-05
-2.1178290891537e-05
-2.06074533302845e-05
-2.00988496730807e-05
-2.13529545239375e-05
-1.95079117325747e-05
-2.19952178777839e-05
-1.96179667799156e-05
-2.02135434871744e-05
-2.05311880645954e-05
-2.10014779649631e-05
-2.0656101461103e-05
-2.03774132048662e-05
-2.25039368450839e-05
-1.93415405376943e-05
-2.12662073048055e-05
-2.01060862635031e-05
-2.08887509611905e-05
-2.04265971394043e-05
-2.10094021794964e-05
-2.05742674689692e-05
-2.08317408706274e-05
-2.09527493148614e-05
-1.98549272909616e-05
-2.09262936676082e-05
-2.12231275239326e-05
-2.02255808468326e-05
-2.07782366117932e-05
-2.08824247573117e-05
-2.06132226020759e-05
-2.04552235218076e-05
-2.16096359568247e-05
-2.09856378023935e-05
-1.94138316490199e-05
-2.18768241646066e-05
-2.06233863888966e-05
-2.10536850998201e-05
-2.16409112772855e-05
-2.04925480594495e-05
-2.10416067044904e-05
-1.97019047207971e-05
-1.95689216210696e-05
-2.11077977375305e-05
-2.0775110113891e-05
-2.05644717892889e-05
-2.16523860233286e-05
-2.06674835730649e-05
-2.06085361745834e-05
-2.00838167260033e-05
-2.00973080889924e-05
-2.0205113464439e-05
-2.14706442308329e-05
-1.89589273163121e-05
-2.00135998710533e-05
-2.04636652685169e-05
-1.88030991126564e-05
-1.97246214164349e-05
-2.08949815898558e-05
-2.01966915851025e-05
-2.02880634609227e-05
-2.11609533845011e-05
-2.00669856240905e-05
-1.97585761570858e-05
-1.96685761506775e-05
-2.10455560730234e-05
-1.9719080327736e-05
-1.93036291951568e-05
-2.05883647141061e-05
-2.05102791631747e-05
-2.06948032622765e-05
-1.95567377213985e-05
-1.96741733037165e-05
-2.05203228269685e-05
-2.01889278159103e-05
-2.03598347672727e-05
-1.9893292945524e-05
-1.98543380228815e-05
-2.03381601329831e-05
-2.05449545326031e-05
-2.00790939829717e-05
-2.013881283443e-05
-2.05705541797146e-05
-2.01147050460139e-05
-1.98844817171906e-05
-2.0006728033211e-05
-2.04179906189614e-05
-2.12881688578327e-05
-1.9446872670347e-05
-1.93585944047077e-05
-2.02877623583802e-05
-1.99696752968111e-05
-1.89863900141978e-05
-2.02920804657874e-05
-2.02273759933247e-05
-2.0627719205847e-05
-2.07580502460253e-05
-2.15742271188341e-05
-1.92107527549373e-05
-1.97397536168253e-05
-2.13562285530294e-05
-1.97240910458304e-05
-2.04223010863094e-05
-1.93478869850007e-05
-2.08384958653194e-05
-1.96954085101723e-05
-1.97526246765073e-05
-2.09462540451642e-05
-1.9562698117818e-05
-1.82042714920859e-05
-1.90251471312212e-05
-1.91110323419925e-05
-1.80786369681913e-05
-1.93925365973786e-05
-2.0378476915506e-05
-1.97398401241589e-05
-1.83156988249959e-05
-1.92155194317972e-05
-1.8918952646772e-05
-2.0388926780142e-05
-2.05750553632517e-05
-1.90597132676875e-05
-1.85262227826705e-05
-1.99575901986038e-05
-1.97917867530859e-05
-1.94468769655973e-05
-1.92236130055264e-05
-1.88935087802237e-05
-1.87512175432116e-05
-1.9393649248047e-05
-1.99624727558898e-05
-1.96217472440422e-05
-2.00296365360452e-05
-1.90161046439336e-05
-1.89918333899595e-05
-1.91195695163909e-05
-1.91841127140832e-05
-1.93685177119985e-05
-1.9344692649286e-05
-2.07578286887812e-05
-1.96114398176777e-05
-1.9524710260029e-05
-1.99171442270634e-05
-1.86976404249611e-05
-1.87515564127419e-05
-1.92489578891279e-05
-1.92827568297597e-05
-2.04442127853162e-05
-1.95628393473741e-05
-1.91462503989795e-05
-2.00435341710382e-05
-2.03688257989089e-05
-2.13565640458157e-05
-2.01654739452376e-05
-1.88144071503482e-05
-2.01615948864878e-05
-1.93068080672324e-05
-1.94300137832712e-05
-1.85288664152604e-05
-2.06229365914369e-05
-2.03470565262503e-05
-1.99226929643367e-05
-1.90270352367261e-05
-1.95427588907334e-05
-2.03502169919855e-05
-1.86379553870339e-05
-1.91989458034706e-05
-1.88864680100371e-05
-1.88210089728365e-05
-1.89631391597233e-05
-1.88373748003121e-05
-2.03127352058147e-05
-2.01840280277493e-05
-1.89222092620683e-05
-1.96817001568772e-05
-1.92753369973323e-05
-1.97025287795749e-05
-2.09317384736788e-05
-1.92610355260373e-05
-1.96063372808034e-05
-1.96766646542491e-05
-2.02062737506402e-05
-1.91633814734201e-05
-1.95407740828545e-05
-1.97693020099062e-05
-1.92781284074526e-05
-1.87828911822138e-05
-2.11511282274285e-05
-1.95714807118274e-05
-2.05284318527808e-05
-1.97002983363268e-05
-2.11120901566675e-05
-2.10228582763275e-05
-1.97556928759349e-05
-2.08394560438211e-05
-1.9794609880139e-05
-2.16000257358092e-05
-1.98599591419307e-05
-2.01830556523682e-05
-2.00184906691069e-05
-1.86607903902216e-05
-1.98452797141816e-05
-1.96957377058057e-05
-2.02529205638473e-05
-2.00868962887055e-05
-1.96656536464383e-05
-1.95679890136025e-05
-2.05573504443458e-05
-2.17745128077409e-05
-2.01627525085582e-05
-1.91647548403129e-05
-1.9373139773465e-05
-2.06066262684016e-05
-1.84082431956166e-05
-1.9861230142378e-05
-2.02765581914437e-05
-1.94485319023315e-05
-1.86190850731088e-05
-2.14522200812884e-05
-2.02048985294623e-05
-1.89954261119919e-05
-1.95311465643664e-05
-1.89668975119702e-05
-1.9182780428627e-05
-1.85923183746784e-05
-2.04467643737406e-05
-1.87147732125311e-05
-2.09689243640391e-05
-2.00494211427929e-05
-2.01627612096068e-05
-1.81394430282378e-05
-2.01470539417748e-05
-1.89218771943743e-05
-1.90207560767479e-05
-1.84471156644694e-05
-1.84229415407162e-05
-1.97979968274226e-05
-1.7682324423936e-05
-2.07666347528495e-05
-1.96465136277522e-05
-2.06860326756157e-05
-2.05285633769285e-05
-1.94935540704934e-05
-1.86885313332796e-05
-1.91787151313472e-05
-2.07140653702615e-05
-1.91527569176873e-05
-1.89737713716694e-05
-1.95995740773534e-05
-1.86742998512319e-05
-1.97869372503023e-05
-2.04091846753982e-05
-1.79544894172641e-05
-1.91779370739285e-05
-1.82712918063922e-05
-1.83508962772381e-05
-1.80226511764017e-05
-1.84159585361138e-05
-1.86445493685006e-05
-1.89626744675092e-05
-1.97360275233271e-05
-1.91001683713048e-05
-2.01406111331518e-05
-2.02708265829874e-05
-1.97831853597242e-05
-1.91094343696894e-05
-1.87610384124987e-05
-1.87698693444762e-05
-1.90027401506582e-05
-1.80104458991133e-05
-1.94805023277146e-05
-1.94301032492517e-05
-1.935610638488e-05
-1.86246442001916e-05
-1.97776084848315e-05
-1.91203711255008e-05
-1.89374550113508e-05
-2.00499780650791e-05
-1.86136094780456e-05
-1.96053486519654e-05
-1.85441371617072e-05
-1.84038731278052e-05
-1.93007937914688e-05
-1.85669211043501e-05
-1.97194740731365e-05
-1.9463683409378e-05
-1.9534708763384e-05
-1.83637278283171e-05
-1.78743788947724e-05
-1.83049782660018e-05
-1.88815556101523e-05
-1.82871481110129e-05
-1.95298083880119e-05
-1.88210598013686e-05
-1.87041248431119e-05
-1.95713539024466e-05
-1.82242759037054e-05
-1.91849203635613e-05
-1.85348398080856e-05
-1.89051487611348e-05
-1.90514358549665e-05
-1.92505641444194e-05
-1.85967300792601e-05
-1.92928665273768e-05
-1.88534483060573e-05
-1.82110007419807e-05
-1.91614052340557e-05
-1.88310245123969e-05
-1.75854870268047e-05
-1.89176101910269e-05
-1.8383301850166e-05
-1.88648502384841e-05
-1.88537424421542e-05
-1.8449542643867e-05
-1.88667609380422e-05
-1.90801377064786e-05
-1.84630124546643e-05
-1.80659381333722e-05
-1.85058640887362e-05
-2.02137792935627e-05
-1.85190134738497e-05
-1.92751147347955e-05
-1.81527184994179e-05
-1.85910596854234e-05
-1.8141736171646e-05
-1.89760934741771e-05
-1.79658698055168e-05
-1.94717642990158e-05
-1.83418209743169e-05
-1.92814565139577e-05
-1.87891131903075e-05
-1.79712301551282e-05
-1.84024738616267e-05
-1.80632473712617e-05
-1.82338086136894e-05
-1.84228761798419e-05
-1.83147467190103e-05
-1.8558503691298e-05
-1.81680038600027e-05
-1.81780810303579e-05
-1.83420192664441e-05
-1.93803868706422e-05
-1.80028415550433e-05
-1.76662226972973e-05
-1.86547612380414e-05
-1.96138788858636e-05
-1.73172106288658e-05
-1.90066058562275e-05
-1.76711045155594e-05
-1.80618106861192e-05
-1.85955666693346e-05
-1.93510216519098e-05
-1.83530373188996e-05
-1.88522771093338e-05
-1.98138543236574e-05
-1.90243281722656e-05
-1.78908600486287e-05
-1.89478340349943e-05
-1.94369104806264e-05
-1.87518060409822e-05
-1.84032018593928e-05
-1.86292361399652e-05
-1.9414804520055e-05
-1.93696085047721e-05
-1.85769710103974e-05
-1.86979765001835e-05
-1.73836690495791e-05
-1.90674017001668e-05
-1.90426074603956e-05
-1.86820486517639e-05
-1.87729201960687e-05
-1.85949960303239e-05
-1.93035297016461e-05
-1.80113249119596e-05
-1.87269630646804e-05
-1.86021504716928e-05
-1.76763496887014e-05
-1.77844659685176e-05
-1.87051463046444e-05
-1.92845933804739e-05
-1.79732849199152e-05
-1.78047774001224e-05
-1.82582442044048e-05
-1.7931485774716e-05
-1.89277801387884e-05
-1.79030831653016e-05
-1.81129311622835e-05
-1.78096471627418e-05
-1.92849587758544e-05
-1.65282013995182e-05
-1.6794000378349e-05
-1.84553229479058e-05
-1.8164101708532e-05
-1.8065266900813e-05
-1.74855918291655e-05
-1.74864114096984e-05
-1.92073490732674e-05
-1.94095548463326e-05
-1.83079178577013e-05
-1.84918772918227e-05
-1.7631392731197e-05
-1.80137803544632e-05
-1.92562517992833e-05
-1.72570391735727e-05
-1.88241412525287e-05
-1.82721297806444e-05
-1.85316959006609e-05
-1.92880340634424e-05
-1.69866601561602e-05
-1.68230298635268e-05
-1.86185407899708e-05
-1.83243159890958e-05
-1.82570501587974e-05
-1.80055946041744e-05
-1.80230352186458e-05
-1.85320076151331e-05
-1.92738991049954e-05
-1.87903483056848e-05
-1.91702387359904e-05
-1.75903394615824e-05
-1.77346365996015e-05
-1.8320609194517e-05
-1.77721259287493e-05
-1.99647418764029e-05
-1.74490963341481e-05
-1.82754853905058e-05
-1.84340979563399e-05
-1.74677911942399e-05
-1.74335629973896e-05
-1.82409021940408e-05
-1.79560961661113e-05
-1.76843748608599e-05
-1.75469432760322e-05
-1.78346662183214e-05
-1.90408254323309e-05
-1.75697252446554e-05
-1.87122192908577e-05
-1.80990661020902e-05
-1.78667233948267e-05
-1.80053973713287e-05
-1.7503628882373e-05
-1.79664708318661e-05
-1.78337364160711e-05
-1.80497569271528e-05
-1.73947587703696e-05
-1.76283765127298e-05
-1.79097675474797e-05
-1.91980830910722e-05
-1.84838050263597e-05
-1.75759316061088e-05
-1.8864197857183e-05
-1.85348932978908e-05
-1.69509128298243e-05
-1.82768555737857e-05
-1.89426224386843e-05
-1.75385952011388e-05
-1.87278165298058e-05
-1.82695137914155e-05
-1.89604835232044e-05
-1.83279122120449e-05
-1.61186388381009e-05
-1.9063116428488e-05
-1.77904402802543e-05
-1.73227571830613e-05
-1.654024643557e-05
-1.80892756501556e-05
-1.81344984072671e-05
-1.74871069690886e-05
-1.8014861446497e-05
-1.92185082209316e-05
-1.7521948809318e-05
-1.69082188716726e-05
-1.73270902672165e-05
-1.77652100282199e-05
-1.6775478743737e-05
-1.92488066362949e-05
-1.85230198250586e-05
-1.81571730164182e-05
-1.86234584131705e-05
-1.77438183071829e-05
-1.7848739112559e-05
-1.87743128165445e-05
-1.86426299545573e-05
-1.84709996874308e-05
-1.67356486921873e-05
-1.86425728148123e-05
-1.71812362726792e-05
-1.84857888855158e-05
-1.90185759569343e-05
-1.6700579880143e-05
-1.76946332696554e-05
-1.90260879678032e-05
-1.86244398473016e-05
-1.70126074737998e-05
-1.61426773382231e-05
-1.78559677929988e-05
-1.75448724958755e-05
-1.77349828627195e-05
-1.82222364976846e-05
-1.77420742964712e-05
-1.7018041604699e-05
-1.67214139768718e-05
-1.82715937266048e-05
-1.76274865342138e-05
-1.92719172790089e-05
-1.63906464235916e-05
-1.7284183240085e-05
-1.80680809791044e-05
-1.74745875435454e-05
-1.827618494947e-05
-1.80179376974992e-05
-1.77835586835778e-05
-1.81334645787055e-05
-1.89280096966975e-05
-1.76902906860703e-05
-1.77924197243752e-05
-1.73990854265375e-05
-1.84661880322124e-05
-1.68948606218632e-05
-1.8317706629024e-05
-1.69160080231284e-05
-1.62711230004717e-05
-1.77092807100757e-05
-1.76404124337173e-05
-1.72515755435728e-05
-1.70077834455608e-05
-1.69924776720484e-05
-1.80530243893679e-05
-1.7713065202976e-05
-1.64592779248547e-05
-1.73822859467303e-05
-1.79959914060589e-05
-1.80979740293215e-05
-1.77857936758995e-05
-1.84994077357982e-05
-1.79848419432726e-05
-1.72045174280791e-05
-1.86313899328419e-05
-1.70631822014671e-05
-1.85874397712464e-05
-1.85272935443392e-05
-1.90815763513215e-05
-1.82893522399941e-05
-1.82186546351387e-05
-1.77825436292447e-05
-1.69851644553379e-05
-1.89008714106018e-05
-1.72800859235055e-05
-1.67454183131966e-05
-1.79500890552867e-05
-1.81146625342059e-05
-1.7560872228586e-05
-1.63288521586868e-05
-1.79337702241361e-05
-1.78206513731476e-05
-1.74310037069734e-05
-1.88154587457765e-05
-1.758802107102e-05
-1.71225980238431e-05
-1.73397231506008e-05
-1.72196460971174e-05
-1.63179325909001e-05
-1.70223047531457e-05
-1.64034063288948e-05
-1.57458640220476e-05
-1.73113243928513e-05
-1.70248037753819e-05
-1.701445832849e-05
-1.68596444301158e-05
-1.62675865424462e-05
-1.63671278812958e-05
-1.70116671644838e-05
-1.71624313304788e-05
-1.62408282456925e-05
-1.66319863543327e-05
-1.65008197832513e-05
-1.66427411126422e-05
-1.59309912002786e-05
-1.87958638630933e-05
-1.8394050702387e-05
-1.69431761053444e-05
-1.76791662906591e-05
-1.71624070924893e-05
-1.60795366184616e-05
-1.67654096358336e-05
-1.78161469416388e-05
-1.680616265589e-05
-1.74545055396037e-05
-1.83230849400544e-05
-1.79269227194886e-05
-1.58662027574374e-05
[...]
-2.34198273967731e-05
-2.47421279557801e-05
-2.41934827841979e-05
-2.35287100860777e-05
-2.40862036004994e-05
-2.40631788211046e-05
-2.38546354795638e-05
-2.47554174591104e-05
-2.3340292530371e-05
-2.55350491073071e-05
-2.5313058222625e-05
-2.45642243475421e-05
-2.49281959739171e-05
-2.55032103544379e-05
-2.38010667982015e-05
-2.36406773638411e-05
-2.37540035406206e-05
-2.49667421209064e-05
-2.36214475848621e-05
-2.37866511272368e-05
-2.36903097677268e-05
-2.44405572931684e-05
-2.51336594895408e-05
-2.49994695517539e-05
-2.44914445909453e-05
-2.39326111874417e-05
-2.42895403766503e-05
-2.37619949887789e-05
-2.45729833648804e-05
-2.4902142188896e-05
-2.48329032173227e-05
-2.54589337007946e-05
-2.42178673145293e-05
-2.44644475273156e-05
-2.45196846090342e-05
-2.41234055067904e-05
-2.51847123976445e-05
-2.44214825381787e-05
-2.62096334509332e-05
-2.48861808214297e-05
-2.44584702705154e-05
-2.46756579861321e-05
-2.41462884261963e-05
-2.41074457625027e-05
-2.50216588187866e-05
-2.52265607931273e-05
-2.35513049767761e-05
-2.50484288320046e-05
-2.47887897986365e-05
-2.50992795271252e-05
-2.40021587127015e-05
-2.41496587562926e-05
-2.30632741072533e-05
-2.50190148789208e-05
-2.33668493130887e-05
-2.47721134524882e-05
-2.38969654242199e-05
-2.46741921945164e-05
-2.47091666612035e-05
-2.50516785837354e-05
-2.48810071873524e-05
-2.42521113607098e-05
-2.52521294367809e-05
-2.41047135922055e-05
-2.43719611258846e-05
-2.5308341212757e-05
-2.46677754222868e-05
-2.55868397435209e-05
-2.46197366570279e-05
-2.41155175277423e-05
-2.41352546556271e-05
-2.50526912671371e-05
-2.42207897010136e-05
-2.52355597328689e-05
-2.42788561678957e-05
-2.38982218044077e-05
-2.60335773371618e-05
-2.42041223690272e-05
-2.47331828387312e-05
-2.49517505517838e-05
-2.4809992124562e-05
-2.54657691882558e-05
-2.58253804580988e-05
-2.54718425970234e-05
-2.41419043415262e-05
-2.45360667993781e-05
-2.43554398239689e-05
-2.57036424573224e-05
-2.42872677792076e-05
-2.38292884922855e-05
-2.68179770602855e-05
-2.50550077760124e-05
-2.48360356337912e-05
-2.49102542986446e-05
-2.49685027369265e-05
-2.50526468847715e-05
-2.46260192743387e-05
-2.54271913143719e-05
-2.48828372779107e-05
-2.47795221156622e-05
-2.49045872669616e-05
-2.47645495703888e-05
-2.59153784806754e-05
-2.54265814996319e-05
-2.42734149470444e-05
-2.55304375895681e-05
-2.49244057770931e-05
-2.60755377202079e-05
-2.53731454615048e-05
-2.53238857805701e-05
-2.63054220712962e-05
-2.47981617112303e-05
-2.59090332949938e-05
-2.5194921022138e-05
-2.5317665300823e-05
-2.4472831062719e-05
-2.47789816063626e-05
-2.48339639969307e-05
-2.54549916582931e-05
-2.47156197385611e-05
-2.59932767991772e-05
-2.4824532068711e-05
-2.51182160767502e-05
-2.44652692003569e-05
-2.49036270595145e-05
-2.49010236803445e-05
-2.41331368354445e-05
-2.46546639354204e-05
-2.44855753798855e-05
-2.55632240743693e-05
-2.60352746954699e-05
-2.45603093797543e-05
-2.51280991162932e-05
-2.55829316088992e-05
-2.58625562670313e-05
-2.45857120157216e-05
-2.54511712088988e-05
-2.50609312117649e-05
-2.52970262462022e-05
-2.50117888953898e-05
-2.52606460205672e-05
-2.58888437418539e-05
-2.5808775360033e-05
-2.5288623202259e-05
-2.4938992501558e-05
-2.60461619578042e-05
nan
-2.62776613008352e-05
-2.5809468679833e-05
-2.49361836582407e-05
-2.55990228122179e-05
-2.58372669286875e-05
-2.50644224142757e-05
-2.55072560691455e-05
-2.39556302019643e-05
-2.65822213323745e-05
-2.49736074878186e-05
-2.54028090688791e-05
-2.48535673904631e-05
-2.51982396384889e-05
-2.52506933131539e-05
-2.49580967605108e-05
-2.60881360556062e-05
-2.6583603411551e-05
-2.63808014170665e-05
-2.58218840836177e-05
-2.4951858770065e-05
-2.62741170956352e-05
-2.64200134221777e-05
-2.66444596947797e-05
-2.55045254307706e-05
-2.54474921963523e-05
-2.62593202820158e-05
-2.57604935165218e-05
-2.60191798213377e-05
-2.51313168622077e-05
-2.45009680054696e-05
-2.65654611774768e-05
-2.62338959348826e-05
-2.58502595729701e-05
-2.56097041243595e-05
-2.56619672388355e-05
-2.53997035956312e-05
-2.6037734373025e-05
-2.60999059645026e-05
-2.65969890246803e-05
-2.60986066320812e-05
-2.55209406508866e-05
-2.50794346771218e-05
-2.63997001584404e-05
-2.56173080702161e-05
-2.5553654345233e-05
-2.71474473802322e-05
-2.62085806144511e-05
-2.52079940488528e-05
-2.53160294942307e-05
-2.56192737871424e-05
-2.61777149338228e-05
-2.51588669701208e-05
-2.62979132132996e-05
-2.49233439194363e-05
-2.60838702412031e-05
-2.60660536366153e-05
-2.618592584737e-05
-2.58052563119984e-05
-2.60792733563608e-05
-2.59931080399429e-05
-2.60397485675296e-05
-2.6145553184527e-05
-2.72741767997886e-05
-2.62650722772503e-05
-2.54966939437221e-05
-2.66783887676899e-05
-2.61055339776952e-05
-2.58326967632327e-05
-2.7617795707785e-05
-2.5493837780009e-05
-2.61709427874977e-05
-2.51557485029474e-05
-2.61801667124064e-05
-2.55484923593411e-05
-2.53322504235123e-05
-2.66609455525215e-05
-2.63452623532873e-05
-2.59599497348264e-05
-2.47898353611737e-05
-2.68261916153282e-05
-2.47510537704553e-05
-2.58483110563145e-05
-2.60245991149247e-05
-2.60203601891333e-05
-2.55158873172931e-05
-2.54554391379805e-05
-2.67439447731621e-05
-2.60665605003747e-05
-2.71489810097764e-05
-2.59060471533331e-05
-2.58539359900046e-05
-2.53965061668436e-05
-2.63692388575898e-05
-2.61797065932244e-05
-2.61323688830349e-05
-2.62965559255326e-05
-2.62642618615895e-05
-2.61132512890743e-05
-2.70294500656676e-05
-2.60112664901726e-05
-2.6711560246192e-05
-2.61244897353756e-05
-2.64447570690824e-05
-2.7062089302237e-05
-2.69413360951988e-05
-2.72706414959975e-05
-2.52517915692984e-05
-2.58736366615466e-05
-2.60332089325208e-05
-2.66079377234444e-05
-2.61168848981471e-05
-2.51470280325866e-05
-2.53920973069078e-05
-2.50773207801013e-05
-2.56101236690659e-05
-2.68032773829041e-05
-2.5807327992953e-05
-2.70828243182712e-05
-2.59790990934606e-05
-2.67610511653404e-05
-2.57478162817667e-05
-2.62424411776945e-05
-2.60959450715196e-05
-2.63479631858891e-05
-2.7236659539008e-05
-2.64377771932072e-05
-2.58947152096373e-05
-2.61186576407284e-05
-2.56516742171461e-05
-2.68874542390536e-05
-2.6506674023838e-05
-2.61694902873787e-05
-2.67221325163309e-05
-2.766744014734e-05
-2.60703277296718e-05
-2.71403257855347e-05
-2.72819257207158e-05
-2.61759440765805e-05
-2.71863194909146e-05
-2.54133712148386e-05
-2.68723500787185e-05
-2.62253491841504e-05
-2.68523082341346e-05
-2.76564311609228e-05
-2.72179386580777e-05
-2.61856131984258e-05
-2.66589032642014e-05
-2.61917818763274e-05
-2.75569530888702e-05
-2.62313407340993e-05
-2.7366848364426e-05
-2.74122803230308e-05
-2.61334430940623e-05
-2.59103505974204e-05
-2.78996813964761e-05
-2.4930615200854e-05
-2.79013687554938e-05
-2.72791421229827e-05
-2.64331083707289e-05
-2.70535749911642e-05
-2.71737429767886e-05
-2.66574697932272e-05
-2.7201041134194e-05
-2.75610616646287e-05
-2.61453508911145e-05
-2.69065514590231e-05
-2.84466685235825e-05
-2.69894206999652e-05
-2.74101492168733e-05
-2.78196711686815e-05
-2.67721103787471e-05
-2.77506141111886e-05
-2.76673832280704e-05
-2.65785506796403e-05
-2.73939843136135e-05
-2.74273124191894e-05
-2.78342341796003e-05
-2.6344993904925e-05
-2.6974152350911e-05
-2.69033026323246e-05
-2.69265937906346e-05
-2.73172231275674e-05
-2.74982383323499e-05
-2.73383922721119e-05
-2.70578723110168e-05
-2.60507773228126e-05
-2.74887391419763e-05
-2.73387722414276e-05
-2.84497819356761e-05
-2.58757850267453e-05
-2.70707994783583e-05
-2.76884860591674e-05
-2.66468647267263e-05
-2.69608880476052e-05
-2.75877422519778e-05
-2.69017247999071e-05
-2.68347277348229e-05
-2.79999458018389e-05
-2.70141740620171e-05
-2.59005345009831e-05
-2.63838224898283e-05
-2.72310877620599e-05
-2.73210786578007e-05
-2.67204927932076e-05
-2.66567920723886e-05
-2.75340608129216e-05
-2.68973875757109e-05
-2.79994082315749e-05
-2.78726808825486e-05
-2.78499877496359e-05
-2.74981733828045e-05
-2.76755549822256e-05
-2.66826339616536e-05
-2.75141980414296e-05
-2.82966560224425e-05
-2.66730440480438e-05
-2.76534273559676e-05
-2.63385949750319e-05
-2.68957080235684e-05
-2.71786082963971e-05
-2.67961678512427e-05
-2.86087851290276e-05
-2.66243626866378e-05
-2.7366205547605e-05
-2.72050249029823e-05
-2.77504779765621e-05
-2.68446806707899e-05
-2.58662900583113e-05
-2.75507375147915e-05
-2.78496963747742e-05
-2.67395131572451e-05
-2.81243921590994e-05
-2.67751867503919e-05
-2.78843667971923e-05
-2.67746338890755e-05
-2.76286158326675e-05
-2.69707739947108e-05
-2.87172095963992e-05
-2.78024926175312e-05
-2.73655741369372e-05
-2.76649717198915e-05
-2.70214414613591e-05
-2.84809813691748e-05
-2.62390329947956e-05
-2.6667290687692e-05
-2.81044228810477e-05
-2.77359785165766e-05
-2.65498581506923e-05
-2.74961733522473e-05
-2.70283616419089e-05
-2.65934595183329e-05
-2.78340918074477e-05
-2.71675895695535e-05
-2.75532788679696e-05
-2.85227548767523e-05
-2.76816216663101e-05
-2.75947082671578e-05
-2.62052123238426e-05
-2.78073558947454e-05
-2.6322919167194e-05
-2.69484228101456e-05
-2.71968418390831e-05
-2.75932186912806e-05
-2.65658081444758e-05
-2.73860573628991e-05
-2.688423438373e-05
-2.83640014334395e-05
-2.72789587912471e-05
-2.75560632425438e-05
-2.79981061286862e-05
-2.86643077227907e-05
-2.65776765583841e-05
-2.81878688096548e-05
-2.78871483184338e-05
-2.73476077629314e-05
-2.74869566466691e-05
-2.82012569546994e-05
-2.63873947335905e-05
-2.70897064187808e-05
-2.73610310684508e-05
-2.82351287831063e-05
-2.75209668924234e-05
-2.74119266998601e-05
-2.75967371269851e-05
-2.75931150075339e-05
-2.76456491882003e-05
-2.8378759147976e-05
-2.67063790444028e-05
-2.85386374099774e-05
-2.78439393273642e-05
-2.77090422042355e-05
-2.83903283590783e-05
-2.77109728273098e-05
-2.78892362984644e-05
-2.73848011015295e-05
-2.74983847700007e-05
-2.81928949529608e-05
-2.78889692216858e-05
-2.80292365911444e-05
-2.91518277376885e-05
-2.78495207319317e-05
-2.75329790412318e-05
-2.88480529132377e-05
-2.768633061787e-05
-2.89275727037413e-05
-2.89510805112265e-05
-2.78922800410147e-05
-2.80587262793653e-05
-2.82096064368524e-05
-2.84229026268202e-05
-2.74427809045503e-05
-2.7749904160695e-05
-2.8365182012775e-05
-2.87675234926342e-05
-2.85362954774202e-05
-2.75575040665809e-05
-2.82790575003027e-05
-2.6819721526757e-05
-2.87600722702849e-05
-2.87458060562126e-05
-2.78928665244191e-05
-2.73098665233041e-05
-2.71596149560077e-05
-2.87121048036497e-05
-2.72904884020788e-05
-2.73803417114655e-05
-2.73718246900931e-05
-2.77178823337911e-05
-2.86489093068435e-05
-2.75185855151415e-05
-2.79459898641305e-05
-2.89101899373844e-05
-2.79523250168727e-05
-2.83045637126686e-05
-2.88453967806776e-05
-2.78722460137961e-05
-2.74183705615594e-05
-2.94009228625348e-05
-2.73917705158022e-05
-2.77796814418947e-05
-2.84541076904199e-05
-2.80845421412656e-05
-2.79788600537025e-05
-2.86069092443072e-05
-2.87046450622041e-05
-2.85947874902428e-05
-2.82857007621442e-05
-2.80680316510899e-05
-2.8107067381263e-05
-2.93566055699113e-05
-2.89732959695199e-05
-2.75412449494861e-05
-2.89383123233967e-05
-2.7238290158819e-05
-2.82565673837734e-05
-2.85572750257981e-05
-2.80469282398579e-05
-2.83296645218884e-05
-2.81308888685633e-05
-2.91344789047538e-05
-2.80051827060845e-05
-2.75972160656632e-05
-2.79530348976764e-05
-2.92434576865452e-05
-2.94238072193917e-05
-2.79930612945198e-05
-2.91534050858046e-05
-2.88478376555864e-05
-2.87810545979675e-05
-2.80261001732418e-05
-2.92878371757881e-05
-2.78577775132284e-05
-2.84582379498749e-05
-2.72548512453242e-05
-2.91072873144867e-05
-2.81002810437633e-05
-2.83664273617349e-05
-2.82225928914553e-05
-2.81708883596998e-05
-2.86001016512582e-05
-2.86742105542853e-05
-2.82270449071734e-05
-2.92445150911561e-05
-2.92681020805033e-05
-2.98118167564049e-05
-2.89971280061233e-05
-2.82935647624646e-05
-2.84285293909664e-05
-2.86805618658123e-05
-2.90176034207166e-05
-2.84860811738724e-05
-2.91450845576786e-05
-2.90131307626082e-05
-3.02446163784422e-05
-2.94682865264506e-05
-2.96654043474439e-05
-2.9875581394123e-05
-2.89230939345434e-05
-2.92672334540021e-05
-2.92197852422893e-05
-2.92535200647673e-05
-2.99648657267648e-05
-2.75197219232211e-05
-2.83365030092753e-05
-2.78812565698318e-05
-2.91276061763006e-05
-2.8277513023656e-05
-2.84350887396188e-05
-2.89651501837858e-05
-2.79753459552261e-05
-2.81548557939903e-05
-2.85079906825146e-05
-2.84556566886147e-05
-2.89056970053031e-05
-3.06582604291323e-05
-2.90697515205928e-05
-2.89359619806148e-05
-2.82775021323768e-05
-2.84513129487625e-05
-2.85817843971059e-05
-2.85778142918576e-05
-2.96644558477501e-05
-2.89283793261409e-05
-2.91844299220572e-05
-2.81682145523392e-05
-2.92398155719389e-05
-2.81764515603918e-05
-2.93372433393013e-05
-2.88416302699346e-05
-2.88387916722073e-05
-2.85967053122832e-05
-2.9154591282282e-05
-2.81035798568387e-05
-2.9708210233056e-05
-2.8663357300433e-05
-2.88977306376193e-05
-2.94286608662394e-05
-2.91311893426571e-05
-2.84185785082421e-05
-2.90860725421262e-05
-2.87412644756824e-05
-2.99059790543417e-05
-2.83161654355629e-05
-3.02583599260322e-05
-2.92356780702708e-05
-3.01090288209417e-05
-2.8978934228148e-05
-2.92615289262573e-05
-2.95395082393087e-05
-2.96259415480143e-05
-2.92097097067871e-05
-2.85738411650023e-05
-2.83741228058986e-05
-2.93442070457066e-05
-2.98201105238351e-05
-2.88054580757284e-05
-2.98833013382722e-05
-2.87245018178593e-05
-2.88038307708106e-05
-2.92634365829284e-05
-2.84698168864533e-05
-3.00929362748666e-05
-2.92531873141784e-05
-2.90969020115633e-05
-2.92918770914919e-05
-2.862866219909e-05
-2.90553931358243e-05
-2.94742131061089e-05
-2.91656557528288e-05
-3.01143445005377e-05
-2.79081601269015e-05
-2.97394267819139e-05
-2.95198708272862e-05
-2.96874988870344e-05
-2.91239414691166e-05
-2.92370543379192e-05
-2.95485275800956e-05
-2.87889049653057e-05
-2.91969865985069e-05
-2.9676399988999e-05
-2.95881201257419e-05
-2.9286881618173e-05
-3.05045762424651e-05
-2.92556132764609e-05
-3.00382718652057e-05
-2.79023527141052e-05
-3.05209763491208e-05
-2.90762863725832e-05
-2.91524276757326e-05
-3.02651264864605e-05
-2.90139463000575e-05
-2.92470102471263e-05
-2.95434827982994e-05
-2.94949264587103e-05
-2.90314426531478e-05
-2.98623828316143e-05
-2.95281820016672e-05
-3.0696426454487e-05
-2.91778914174604e-05
-2.95618450367e-05
-2.99331922672894e-05
-3.01782102148111e-05
-2.88226991276961e-05
-2.9086649180582e-05
-3.00522594257228e-05
-2.9909609609727e-05
-2.92663928599575e-05
-3.06502428982301e-05
-2.90725852314969e-05
-2.91770547464373e-05
-2.99378887012926e-05
-3.00878562181623e-05
-2.9443434569455e-05
-2.90683304850328e-05
-2.97417938089086e-05
-2.92862515963641e-05
-2.90776247244555e-05
-2.94646595633108e-05
-2.94976519046981e-05
-3.02390208135131e-05
-3.00784455267911e-05
-2.93932545140768e-05
-3.02019089465265e-05
-2.87338626513496e-05
-2.97671675161304e-05
-3.11157393895858e-05
-2.96254141341701e-05
-2.99978258925421e-05
-2.96844120332199e-05
-2.94760111246076e-05
-2.95182316242622e-05
-2.93633562978061e-05
-3.02980158449604e-05
-3.08948535478069e-05
-2.93939370220401e-05
-2.82445672225679e-05
-2.87034778969419e-05
-2.97147867546178e-05
-2.99989344574218e-05
-3.05389595998013e-05
-3.02893026238634e-05
-3.04766975414222e-05
-2.9936233465845e-05
-2.9757562553306e-05
-2.93374955224305e-05
-3.02889738375158e-05
-3.09594152288913e-05
-3.00073386074318e-05
-2.95296060916192e-05
-3.10973352564849e-05
-2.97329894575636e-05
-2.97922564666095e-05
-2.99064586634453e-05
-3.11477348640156e-05
-3.07024455485304e-05
-3.07166836467153e-05
-3.10619649184729e-05
-3.01414926731088e-05
-3.01223638012216e-05
-3.00007094495685e-05
-3.16219552987524e-05
-3.13652751412035e-05
-3.00692157285839e-05
-3.03261542711748e-05
-3.13645858042306e-05
-2.92437789102667e-05
-2.97132177653198e-05
-2.9742979645329e-05
-2.9614966695319e-05
-3.01765240533316e-05
-3.01716242852326e-05
-2.96280470377931e-05
-2.87151086494099e-05
-2.95925169214399e-05
-3.06255946876468e-05
-3.03964950986766e-05
-2.91950830783284e-05
-3.02766008320269e-05
-3.08995928358955e-05
-3.05766018232821e-05
-2.97919426357923e-05
-3.04626839435352e-05
-3.09209084041087e-05
-3.04784098094006e-05
-2.91556177533166e-05
-2.92776831006722e-05
-3.04679685608746e-05
-3.05180141865964e-05
-3.12806938665779e-05
-3.014112965499e-05
-2.95451696735582e-05
-2.98445230909711e-05
-3.02437983750987e-05
-2.94170792846154e-05
-3.03757723226636e-05
-3.04445565571861e-05
-2.99030970290421e-05
-3.09015137194663e-05
-2.982180130656e-05
-3.07552897461109e-05
-2.98473309749886e-05
-3.11039020152463e-05
-2.97861274439327e-05
-2.9506811094836e-05
-3.12035101553779e-05
-3.14932297357815e-05
-2.95273329456169e-05
-3.04553975562715e-05
-3.10880757892928e-05
-2.9066062812958e-05
-3.07175163184398e-05
-3.00297598262054e-05
-3.06553877744374e-05
-2.98162753013236e-05
-3.11996362856147e-05
-2.86760879437809e-05
-2.92308639616617e-05
-3.07922100248034e-05
-3.0485618390062e-05
-2.99282530644103e-05
-3.01056329845196e-05
-3.0784890424436e-05
-3.04361139567043e-05
-2.99175462067786e-05
-3.02223848120769e-05
-2.93620819968343e-05
-2.92248136169518e-05
-3.01924099824735e-05
-3.08613408589767e-05
-2.99565011316226e-05
-2.98658282698409e-05
-3.18006342222581e-05
-3.10388737877111e-05
-3.01576979707323e-05
-3.00296872260696e-05
-3.04969726171855e-05
-2.95881636430121e-05
-3.09494925385716e-05
-3.07107033131962e-05
-3.11386980541992e-05
-3.0509613827239e-05
-3.10977023419186e-05
-3.19162305733275e-05
-3.1424821728229e-05
-3.11575661196476e-05
-2.94096992680015e-05
-3.11588071567958e-05
-3.00691407539624e-05
-3.02835078533513e-05
-2.92777784253364e-05
-3.13356575745027e-05
-3.20864539100519e-05
-3.14736277422209e-05
-3.07911307237694e-05
-2.9896661683559e-05
-3.10521033376583e-05
-3.13545265602835e-05
-2.97778651384871e-05
-3.10882157760825e-05
-2.92793299685118e-05
-2.99449637204726e-05
-3.019640210319e-05
-3.05275933963179e-05
-2.94959457410054e-05
-3.03811608143153e-05
-2.96851623995548e-05
-3.19521067235333e-05
-3.12584541846913e-05
-3.10270765915959e-05
-3.02824515684653e-05
-3.20911951906745e-05
-3.08448530906585e-05
-3.10468531684626e-05
-3.09441352388222e-05
-3.11091570217298e-05
-2.9400428948141e-05
-3.0457696110835e-05
-3.15453501502e-05
-3.09643374758821e-05
-3.09958676617155e-05
-3.09810468470859e-05
-3.09578404809131e-05
-3.10921929146165e-05
-3.01957951650571e-05
-2.96736567451295e-05
-3.06132232314655e-05
-3.13015736563475e-05
-2.96425602223553e-05
-3.17661299386985e-05
-3.06725716519169e-05
-3.11778381542456e-05
-3.08883091691718e-05
-3.1215850724506e-05
-3.21755898429115e-05
-3.16647982591205e-05
-3.0351391054613e-05
-3.06012867504927e-05
-3.03035510684772e-05
-3.11339243018986e-05
-3.08476542121401e-05
-3.08372002782859e-05
-3.07195901639439e-05
-3.12405513247013e-05
-3.03791628964089e-05
-3.07941492648085e-05
-3.04215492719574e-05
-3.05125166721889e-05
-3.22536907646487e-05
-3.05308974318368e-05
-3.16634596363696e-05
-3.09855830498542e-05
-3.1007582336206e-05
-3.13780624488313e-05
-3.13408981456291e-05
-3.02616070769983e-05
-3.11697625376461e-05
-2.9704684330121e-05
-3.15366581915321e-05
-3.20517195410837e-05
-2.96593955485601e-05
-3.18883303397778e-05
-3.03463602495409e-05
-3.07244608804943e-05
-3.07580461936104e-05
-3.14349913304019e-05
-3.20527380911345e-05
-3.12935456937404e-05
-3.24633946068787e-05
-3.0508720487233e-05
-3.0499432020879e-05
-3.1037176779906e-05
-3.1063798203261e-05
-3.10769163864701e-05
-3.04656460350406e-05
-3.27423166549926e-05
-3.14700291930733e-05
-3.01956494495071e-05
-3.12489401895615e-05
-3.10399418790647e-05
-3.14679958813933e-05
-3.16022151497764e-05
-3.11551890995248e-05
-3.21893084703726e-05
-3.12490606733854e-05
-3.20225193498774e-05
-3.1934753951018e-05
-3.23266527907901e-05
-3.23965195014142e-05
-3.24810839312022e-05
-3.12301709771657e-05
-3.07123803705144e-05
-3.1756923519973e-05
-3.16821166566441e-05
-3.03618259931646e-05
-3.13457713085497e-05
-3.22309622620995e-05
-3.0657191848448e-05
-3.234395516236e-05
-3.26651371951199e-05
-3.06531515442016e-05
-3.253144237465e-05
-3.21768606245695e-05
-3.10353591104652e-05
-3.27282748444139e-05
-3.10305282256e-05
-3.15097298246545e-05
-3.13022302407634e-05