File: doc/demo/VSM Sample Data.DAT
[Header]
; VSM Data File (default extension .dat)
; Copyright (c) 2003-2013, Quantum Design, Inc. All rights reserved.
TITLE,
FILEOPENTIME,3900589104.8775,08/07/2023,4:57 pm
BYAPP,VSM,1.0,1.0
INFO,DYNACOOL VSM Option Release 1.4.10 Build 1,APPNAME
INFO,Quantum Design Linear Motor Servo Controller,MOTOR_MODULE_NAME
INFO,3101-100 N2,MOTOR_HW_VERSION
INFO,MMC1154,MOTOR_SERIAL_NUMBER
INFO,SRV No X-over 01.03.11,MOTOR_SOFTWARE_VERSION
INFO,Quantum Design VSM Detection Module,VSM_MODULE_NAME
INFO,3101-150 F0,VSM_HW_VERSION
INFO,VSM783,VSM_SERIAL_NUMBER
INFO,VSM No X-over 01.02.05 May 20 2008 13:51:47,VSM_SOFTWARE_VERSION
INFO,771,PREAMP_SERIAL_NUMBER
INFO,LB776,COIL_SERIAL_NUMBER
INFO,0,MOMENT_UNITS
INFO,Glass w 3d,SAMPLE_MATERIAL
INFO,QD Brass ,SAMPLE_COMMENT
INFO,,SAMPLE_MASS
INFO,,SAMPLE_VOLUME
INFO,,SAMPLE_MOLECULAR_WEIGHT
INFO,,SAMPLE_SIZE
INFO,,SAMPLE_SHAPE
DATATYPE,COMMENT,1
DATATYPE,TIME,2
STARTUPAXIS,X,2
STARTUPAXIS,Y1,5
[Data]
Comment,Time Stamp (sec),Temperature (K),Magnetic Field (Oe),Moment (emu),M. Std. Err. (emu),Transport Action,Averaging Time (sec),Frequency (Hz),Peak Amplitude (mm),Center Position (mm),Coil Signal' (mV),Coil Signal" (mV),Range (mV),M. Quad. Signal (emu),M. Raw' (emu),M. Raw" (emu),Min. Temperature (K),Max. Temperature (K),Min. Field (Oe),Max. Field (Oe),Mass (grams),Motor Lag (deg),Pressure (Torr),VSM Status (code),Motor Status (code),Measure Status (code),Measure Count,System Temp. (K),Temp. Status (code),Field Status (code),Chamber Status (code),Motor Current (amps),Motor Heatsink Temp. (C),Map 01,Map 02,Map 03,Map 04,Map 05,Map 06,Map 07,Map 08,Map 09,Map 10,Map 11,Map 12,Map 13,Map 14,Map 15,Map 16
,3900589109.319,300.240777954676,3000.16040039063,,,2,,,,55.9430001358986,,,,,,,300.240777954676,300.240777954676,3000.16040039063,3000.16040039063,,,34.2788391113281,,,,,298.339080810547,0,0,0,0.0244140625,26.3929634094238,,,,,,,,,,,,,,,,
,3900589135.5455,300.234100341797,2898.328125,0.000121069869087186,2.6642929992462E-6,1,0.499626677034896,40.0298881530762,2.00251642642921,55.9299997985363,0.000609957292996718,0.000122701484144867,0.25,1.79055148819296E-6,0.000121040922376326,2.25717820433446E-6,300.229217529297,300.229217529297,2895.80883789063,2900.84741210937,48.9760613864859,20.5936454772563,34.3017692565918,0,0,0,20,298.330474853516,1,6,1,2.2259521484375,32.7468223571777,,,,,,,,,,,,,,,,
,3900589147.0825,300.237762451172,2782.84484863281,0.000114873479617321,2.02942453865908E-6,1,0.499626677034896,40.0298881530762,2.00262087693394,55.9399984776974,0.000581657180928847,0.000100883720384307,0.25,-1.37771886392643E-6,0.00011485786853719,-9.34417149872504E-7,300.236297607422,300.236297607422,2780.8681640625,2784.82153320313,48.261652919909,20.5952570161423,34.3255081176758,0,0,0,20,298.326354980469,1,6,1,2.2314453125,33.7243423461914,,,,,,,,,,,,,,,,
,3900589158.5075,300.229736328125,2668.86694335938,0.000111599898774964,1.90161393360468E-6,1,0.499626677034896,40.0298881530762,2.00197809920293,55.9200011193752,0.000563899664714641,0.000103389747857482,0.25,-2.67019506911139E-7,0.000111580624938428,1.63470959332061E-7,300.229034423828,300.229034423828,2666.8701171875,2670.86376953125,47.719984356082,20.6002765760232,34.3360290527344,0,0,0,20,298.317413330078,1,6,1,2.22732543945313,34.7018585205078,,,,,,,,,,,,,,,,
,3900589170.0095,300.229156494141,2554.38354492187,0.000107177510641864,1.67911652139198E-6,1,0.499626677034896,40.0298881530762,2.00217152226146,55.9299997985363,0.00053978764154214,0.000109081167890686,0.25,1.67959825257807E-6,0.000107151534661528,2.09268133990109E-6,300.233917236328,300.233917236328,2551.92138671875,2556.845703125,48.4633130778705,20.5950965247681,34.3621940612793,0,0,0,20,298.3173828125,1,6,1,2.20870971679687,36.1681327819824,,,,,,,,,,,,,,,,
,3900589181.511,300.22705078125,2439.41442871094,9.79519851318148E-5,2.05156211488729E-6,1,0.499626677034896,40.0298881530762,2.00169935222726,55.9399984776974,0.000497058954586716,7.89620808425119E-5,0.25,-2.56539530996004E-6,9.79440662561574E-5,-2.18711751334547E-6,300.229370117188,300.229370117188,2436.93334960938,2441.8955078125,48.4711293630628,20.5932950048341,34.372444152832,0,0,0,20,298.315826416016,1,6,1,2.22000122070313,35.6793746948242,,,,,,,,,,,,,,,,
,3900589192.9765,300.229263305664,2324.18859863281,9.61604172648957E-5,1.73310715827568E-6,1,0.499626677034896,40.0298881530762,2.00126896578423,55.9399984776974,0.000486685767046277,8.38504882336039E-5,0.25,-1.26099436485069E-6,9.61477868085711E-5,-8.89864588274786E-7,300.228515625,300.228515625,2321.69555664062,2326.681640625,48.8822659641782,20.5928132859997,34.3802680969238,0,0,0,20,298.316162109375,1,6,1,2.22900390625,36.6568908691406,,,,,,,,,,,,,,,,
,3900589204.4945,300.22492980957,2209.27856445313,9.12849623785862E-5,2.39312361577963E-6,1,0.499626677034896,40.0298881530762,2.00145481445882,55.9299997985363,0.000461032817381329,8.50909374537717E-5,0.25,-1.10872376158723E-7,9.12687935914364E-5,2.41251586113598E-7,300.226043701172,300.226043701172,2206.80639648438,2211.75073242187,50.2079079327938,20.591352002964,34.4104804992676,0,0,0,20,298.311920166016,1,6,1,2.20962524414062,36.1681327819824,,,,,,,,,,,,,,,,
,3900589215.9785,300.22819519043,2094.279296875,8.74141123860794E-5,2.72731293954642E-6,1,0.499626677034896,40.0298881530762,2.00110440898554,55.9299997985363,0.000442019907576927,7.81755696473185E-5,0.25,-7.58501036193389E-7,8.74011371851672E-5,-4.21191896991344E-7,300.231872558594,300.231872558594,2091.78491210938,2096.77368164062,48.4859803049282,20.5880460464805,34.4158744812012,0,0,0,20,298.304229736328,1,6,1,2.21954345703125,36.1681327819824,,,,,,,,,,,,,,,,
,3900589227.4485,300.217987060547,1980.2822265625,8.06438120001932E-5,1.60300752405646E-6,1,0.499626677034896,40.0298881530762,2.0014761447899,55.9299997985363,0.000408529907938573,6.85227140158177E-5,0.25,-1.41493260662614E-6,8.06346233457951E-5,-1.10360390205337E-6,300.219970703125,300.219970703125,1977.80163574219,1982.76281738281,49.1785031729667,20.5908911048052,34.4382629394531,0,0,0,20,298.298706054687,1,6,1,2.2125244140625,39.1006851196289,,,,,,,,,,,,,,,,
,3900589238.9665,300.219177246094,1864.74597167969,7.70272970485318E-5,1.95805525944058E-6,1,0.499626677034896,40.0298881530762,2.00157985378612,55.9200011193752,0.00039008713770348,6.6215529675201E-5,0.25,-1.20048772221219E-6,7.70179353019291E-5,-9.03147464827366E-7,300.219299316406,300.219299316406,1862.80834960938,1866.68359375,48.9604288161013,20.5848201512482,34.449592590332,0,0,0,20,298.300231933594,1,6,1,2.21633911132813,38.1231689453125,,,,,,,,,,,,,,,,
,3900589250.454,300.21614074707,1749.87469482422,7.16771149830359E-5,1.62658339998198E-6,1,0.499626677034896,40.0298881530762,2.00190322591709,55.9299997985363,0.00036064466643594,7.45672421336974E-5,0.25,1.44528879993474E-6,7.16585252100642E-5,1.72151617114309E-6,300.216827392578,300.216827392578,1747.86291503906,1751.88647460938,48.8033214837359,20.5817287083249,34.4628105163574,0,0,0,20,298.296173095703,1,6,1,2.22671508789062,37.1456527709961,,,,,,,,,,,,,,,,
,3900589261.9405,300.218978881836,1634.91815185547,6.77021610634032E-5,2.30214304566519E-6,1,0.499626677034896,40.0298881530762,2.00189186273145,55.9299997985363,0.000342270466881996,6.1671855993783E-5,0.25,-3.69324979042239E-7,6.76912872630593E-5,-1.08102424514407E-7,300.216003417969,300.216003417969,1632.95068359375,1636.88562011719,48.830678481909,20.5859090290074,34.4843902587891,0,0,0,20,298.296081542969,1,6,1,2.20596313476562,39.5894432067871,,,,,,,,,,,,,,,,
,3900589273.4275,300.211471557617,1520.12554931641,6.15892715368858E-5,2.74020325494191E-6,1,0.499626677034896,40.0298881530762,2.00156819604385,55.9399984776974,0.000312094268674205,5.19152921926217E-5,0.25,-1.1636421986428E-6,6.15825851131522E-5,-9.25846903346891E-7,300.212738037109,300.212738037109,1518.1162109375,1522.13488769531,48.911967847909,20.5818544229356,34.488166809082,0,0,0,20,298.298309326172,1,6,1,2.23068237304687,37.6344108581543,,,,,,,,,,,,,,,,
,3900589284.919,300.21305847168,1405.12524414062,5.71268487683787E-5,2.24438404292061E-6,1,0.499626677034896,40.0298881530762,2.00132731241789,55.9299997985363,0.00028938294128942,4.84967484249674E-5,0.25,-1.01028915530474E-6,5.7120377813883E-5,-7.89735654391094E-7,300.211120605469,300.211120605469,1403.10095214844,1407.14953613281,48.5524187290628,20.5783524299429,34.4868202209473,0,0,0,20,298.295623779297,1,6,1,2.21237182617187,38.6119270324707,,,,,,,,,,,,,,,,
,3900589296.4025,300.212524414063,1290.21459960938,5.2815041226095E-5,2.14864325770295E-6,1,0.499626677034896,40.0298881530762,2.00163807795189,55.9299997985363,0.000267973645180634,4.27320977024623E-5,0.25,-1.35207300214189E-6,5.28106720050335E-5,-1.14808880457333E-6,300.209594726562,300.209594726562,1288.23071289062,1292.19848632812,48.6821690632552,20.581939787852,34.4943733215332,0,0,0,20,298.295745849609,1,6,1,2.215576171875,38.1231689453125,,,,,,,,,,,,,,,,
,3900589307.9155,300.210968017578,1175.248046875,4.79906323783823E-5,1.37406486671869E-6,1,0.499626677034896,40.0298881530762,2.00171303785248,55.9299997985363,0.000244888068325004,3.1383831830909E-5,0.25,-2.70309252972205E-6,4.79923524890527E-5,-2.51747154913281E-6,300.213348388672,300.213348388672,1173.25476074219,1177.24133300781,49.044063067659,20.584100977932,34.491943359375,0,0,0,20,298.285217285156,1,6,1,2.2161865234375,39.1006851196289,,,,,,,,,,,,,,,,
,3900589319.3895,300.208770751953,1060.66015625,4.28359365411893E-5,2.2887983285135E-6,1,0.499626677034896,40.0298881530762,2.0015895260447,55.9399984776974,0.00021832211284633,2.93528561364325E-5,0.25,-2.14706293248375E-6,4.28364496190397E-5,-1.98142546533713E-6,300.208770751953,300.208770751953,1058.22766113281,1063.09265136719,49.3684389031398,20.5788112015522,34.5046234130859,0,0,0,20,298.292175292969,1,6,1,2.21176147460938,39.5894432067871,,,,,,,,,,,,,,,,
,3900589330.896,300.208358764648,945.807189941406,3.81505328964963E-5,2.04841913775252E-6,1,0.499626677034896,40.0298881530762,2.00145807229961,55.9299997985363,0.000193596589637413,3.0623255682039E-5,0.25,-1.02444195546779E-6,3.8147565476826E-5,-8.77081860138508E-7,300.209808349609,300.209808349609,943.32763671875,948.286743164062,48.5547636146205,20.5833025257366,34.5151443481445,0,0,0,20,298.286407470703,1,6,1,2.2235107421875,39.5894432067871,,,,,,,,,,,,,,,,
,3900589342.3795,300.207626342773,830.814727783203,3.42322866743224E-5,1.69407548543401E-6,1,0.499626677034896,40.0298881530762,2.00137422642339,55.9299997985363,0.000173137615684051,3.05367894190527E-5,0.25,-3.13221999319564E-7,3.42272868629324E-5,-1.81105265216694E-7,300.207489013672,300.207489013672,828.296081542969,833.333374023437,48.7454809733128,20.577764342331,34.5235061645508,0,0,0,20,298.278839111328,1,6,1,2.21633911132813,40.0782012939453,,,,,,,,,,,,,,,,
,3900589353.8595,300.200698852539,715.506317138672,2.83877869143141E-5,1.63510670985328E-6,1,0.499626677034896,40.0298881530762,2.00105788867625,55.9399984776974,0.000145601465865918,1.43099713253512E-5,0.25,-2.44052580558376E-6,2.83920593952168E-5,-2.33056677494204E-6,300.197601318359,300.197601318359,713.087890625,717.924743652344,48.9612104446206,20.5852667023998,34.5337562561035,0,0,0,20,298.280578613281,1,6,1,2.23800659179687,40.5669593811035,,,,,,,,,,,,,,,,
,3900589365.3515,300.197647094727,600.551727294922,2.30651106983118E-5,1.58792302399398E-6,1,0.499626677034896,40.0298881530762,2.00097087014093,55.9299997985363,0.000120858434925154,-2.16128691851191E-6,0.25,-4.71416016318256E-6,2.30791211144728E-5,-4.62432234513211E-6,300.196868896484,300.196868896484,598.042785644531,603.060668945313,49.565409289986,20.577796286853,34.5475158691406,0,0,0,20,298.281921386719,1,6,1,2.22686767578125,40.0782012939453,,,,,,,,,,,,,,,,
,3900589376.858,300.195129394531,485.604248046875,1.95974729497306E-5,1.3240374273671E-6,1,0.499626677034896,40.0298881530762,2.00144874239464,55.9299997985363,9.84381768090056E-5,2.11642084190707E-5,0.25,5.49829240229696E-7,1.95918043505609E-5,6.25337062919244E-7,300.195129394531,300.195129394531,483.053527832031,488.154968261719,48.5188087027359,20.5839696797029,34.5521011352539,0,0,0,20,298.28076171875,1,6,1,2.20748901367187,40.0782012939453,,,,,,,,,,,,,,,,
,3900589388.3585,300.195709228516,370.64826965332,1.47852813935073E-5,2.30781687207825E-6,1,0.499626677034896,40.0298881530762,2.0013295749806,55.9299997985363,7.60963672918187E-5,6.09597021943282E-6,0.25,-1.5400917888773E-6,1.47885465496465E-5,-1.48277099145744E-6,300.195709228516,300.195709228516,368.163757324219,373.132781982422,49.2293090267167,20.583136510561,34.5690956115723,0,0,0,20,298.272064208984,1,6,1,2.2186279296875,39.5894432067871,,,,,,,,,,,,,,,,
,3900589399.8265,300.193206787109,255.65486907959,9.80635637721421E-6,1.38790670294638E-6,1,0.499626677034896,40.0298881530762,2.00149089939773,55.9299997985363,5.09883489587779E-5,1.28075759741474E-6,0.25,-1.56860311815671E-6,9.81063361580827E-6,-1.53048553084797E-6,300.193206787109,300.193206787109,253.11491394043,258.19482421875,47.8348837484089,20.5712123713852,34.5771865844727,0,0,0,20,298.271270751953,1,6,1,2.22335815429687,40.5669593811035,,,,,,,,,,,,,,,,
,3900589411.335,300.201019287109,141.227226257324,4.54133309655193E-6,1.54090166007991E-6,1,0.499626677034896,40.0298881530762,2.00103164991409,55.9299997985363,2.4756324944292E-5,-5.58949599101142E-6,0.25,-1.95108666751668E-6,4.54803755013051E-6,-1.93321280081911E-6,300.201019287109,300.201019287109,139.228286743164,143.226165771484,48.9979469850244,20.5780325300044,34.5839309692383,0,0,0,20,298.271301269531,1,6,1,2.20413208007813,40.0782012939453,,,,,,,,,,,,,,,,
,3900589422.801,300.197357177734,26.6906147003174,-1.01681073671913E-6,1.79797299309863E-6,1,0.499626677034896,40.0298881530762,2.00161576847898,55.9299997985363,-3.08077693284116E-6,-1.20068560821901E-5,0.25,-2.18877196248209E-6,-1.00818222345619E-6,-2.19229852790398E-6,300.195983886719,300.195983886719,24.1959247589111,29.1853046417236,48.8822659641782,20.5735302483991,34.5912132263184,0,0,0,20,298.278625488281,1,6,1,2.22305297851562,41.055721282959,,,,,,,,,,,,,,,,
,3900589434.3035,300.187606811523,-88.7392845153809,-4.64126693317512E-6,1.8076051508385E-6,1,0.499626677034896,40.0298881530762,2.00133731824142,55.9399984776974,-2.00292096067887E-5,-2.2677406149932E-5,0.25,-3.62896057113388E-6,-4.62642653675385E-6,-3.64621133147723E-6,300.1875,300.1875,-90.7327194213867,-86.745849609375,49.1816296870437,20.5711911666886,34.6117134094238,0,0,0,20,298.271667480469,1,6,1,2.2296142578125,41.055721282959,,,,,,,,,,,,,,,,
,3900589445.8095,300.183227539063,-203.731506347656,-7.36635777807921E-6,2.41925448712772E-6,1,0.499626677034896,40.0298881530762,2.00093226057433,55.9299997985363,-3.55422784106597E-5,-1.57547036878682E-5,0.25,-1.75210068383574E-6,-7.35826677476474E-6,-1.7802053118895E-6,300.183227539063,300.183227539063,-205.733474731445,-201.729537963867,48.3210566873705,20.576453918538,34.6154899597168,0,0,0,20,298.268646240234,1,6,1,2.20977783203125,40.5669593811035,,,,,,,,,,,,,,,,
,3900589457.294,300.188491821289,-318.223785400391,-1.29357208546219E-5,2.09277834060832E-6,1,0.499626677034896,40.0298881530762,2.00081311925023,55.9500008821487,-6.29245959634845E-5,-2.48980850259697E-5,0.25,-2.5287370029964E-6,-1.29236254815972E-5,-2.57818762484068E-6,300.190551757812,300.190551757812,-320.778717041016,-315.668853759766,48.7251586318128,20.5839154228304,34.6284408569336,0,0,0,20,298.267669677734,1,6,1,2.23526000976562,41.055721282959,,,,,,,,,,,,,,,,
,3900589468.7805,300.186767578125,-433.14289855957,-1.91365568084909E-5,2.54939295342866E-6,1,0.499626677034896,40.0298881530762,2.00082119697879,55.9399984776974,-9.47030582748086E-5,-2.81438193247549E-5,0.25,-2.01945978592067E-6,-1.91253059559903E-5,-2.0929264672189E-6,300.184906005859,300.184906005859,-435.679565429687,-430.606231689453,48.7923786844667,20.5744701239694,34.6384201049805,0,0,0,20,298.264953613281,1,6,1,2.22366333007813,40.0782012939453,,,,,,,,,,,,,,,,
,3900589480.28,300.18244934082,-548.169281005859,-2.25789549031026E-5,1.92622652718147E-6,1,0.499626677034896,40.0298881530762,2.00123670900789,55.9399984776974,-0.000111744127790528,-3.33061343368966E-5,0.25,-2.40113651421894E-6,-2.25656118253752E-5,-2.48781683045644E-6,300.183380126953,300.183380126953,-550.631652832031,-545.706909179687,48.6774792921398,20.584036551873,34.6591911315918,0,0,0,20,298.263824462891,1,6,1,2.22946166992187,41.055721282959,,,,,,,,,,,,,,,,
,3900589491.7715,300.178649902344,-663.0859375,-2.87863850392732E-5,2.27199705673321E-6,1,0.499626677034896,40.0298881530762,2.0008914627597,55.9299997985363,-0.000144028856368125,-3.39108476187536E-5,0.25,-1.36855118758767E-6,-2.87759075299143E-5,-1.47936876912775E-6,300.177734375,300.177734375,-665.59228515625,-660.57958984375,48.0787518464089,20.5831312556309,34.6648559570313,0,0,0,20,298.263519287109,1,6,1,2.22122192382813,41.055721282959,,,,,,,,,,,,,,,,
,3900589503.2585,300.179061889648,-778.096984863281,-3.04714673733639E-5,2.04258316823872E-6,1,0.499626677034896,40.0298881530762,2.00095687666017,55.9299997985363,-0.000150969138199479,-4.39458311682652E-5,0.25,-3.04307532116211E-6,-3.04542247118641E-5,-3.16009113393146E-6,300.174438476562,300.174438476562,-780.599731445313,-775.59423828125,49.0886158932552,20.5850604294966,34.6678237915039,0,0,0,20,298.265350341797,1,6,1,2.2235107421875,42.0332374572754,,,,,,,,,,,,,,,,
,3900589514.734,300.180755615234,-893.161743164062,-3.70805999971978E-5,1.58017104300204E-6,1,0.499626677034896,40.0298881530762,2.00095057923618,55.9399984776974,-0.000185849414355847,-4.1981036127429E-5,0.25,-1.4257599444804E-6,-3.70684023398667E-5,-1.56856532660088E-6,300.183776855469,300.183776855469,-895.648071289063,-890.675415039063,47.0618531428896,20.5752288134157,34.6734886169434,0,0,0,20,298.253540039063,1,6,1,2.20565795898438,40.0782012939453,,,,,,,,,,,,,,,,
,3900589526.239,300.173110961914,-1008.1682434082,-4.23413167537263E-5,2.6720226963504E-6,1,0.499626677034896,40.0298881530762,2.00112499890578,55.9299997985363,-0.000210226872590003,-5.87443371204807E-5,0.25,-3.76791403831882E-6,-4.23191413602272E-5,-3.93059791634995E-6,300.174591064453,300.174591064453,-1010.65362548828,-1005.68286132813,49.0729833228706,20.579577499331,34.6807708740234,0,0,0,20,298.238983154297,1,6,1,2.20535278320313,42.0332374572754,,,,,,,,,,,,,,,,
,3900589537.7315,300.169662475586,-1122.67236328125,-4.61164992399253E-5,1.52277782532807E-6,1,0.499626677034896,40.0298881530762,2.00090831846295,55.9399984776974,-0.000231434626082481,-5.05869330577473E-5,0.25,-1.45165487519042E-6,-4.6102584062878E-5,-1.62932369636271E-6,300.169921875,300.169921875,-1125.67553710938,-1119.66918945312,48.2647794339859,20.5786000124185,34.6872444152832,0,0,0,20,298.246002197266,1,6,1,2.20077514648438,42.5219955444336,,,,,,,,,,,,,,,,
,3900589549.2695,300.170074462891,-1238.57781982422,-5.32189024768511E-5,2.91348193368949E-6,1,0.499626677034896,40.0298881530762,2.00101748044299,55.9399984776974,-0.000265116467104357,-6.90124445708806E-5,0.25,-3.78119733596056E-6,-5.31947184016935E-5,-3.98584759755146E-6,300.170074462891,300.170074462891,-1240.58605957031,-1236.56958007812,47.7074782997743,20.5779715616833,34.720157623291,0,0,0,20,298.250335693359,1,6,1,2.22030639648438,40.5669593811035,,,,,,,,,,,,,,,,
,3900589560.7165,300.167861938477,-1352.64239501953,-5.58324064761432E-5,2.26677670027039E-6,1,0.499626677034896,40.0298881530762,2.00096617988153,55.9399984776974,-0.000279806198757494,-6.33741748284489E-5,0.25,-2.17898837959469E-6,-5.58139364690943E-5,-2.39401176083006E-6,300.167510986328,300.167510986328,-1355.66955566406,-1349.615234375,48.8228621967167,20.5824007323348,34.7247428894043,0,0,0,20,298.252990722656,1,6,1,2.22442626953125,43.49951171875,,,,,,,,,,,,,,,,
,3900589572.324,300.170806884766,-1468.52020263672,-6.27448878240895E-5,1.26565980249022E-6,1,0.499626677034896,40.0298881530762,2.00098733785261,55.9299997985363,-0.00031288425984358,-7.96555203199306E-5,0.25,-4.11954393357224E-6,-6.27176800541114E-5,-4.360882997364E-6,300.173950195313,300.173950195313,-1469.57019042969,-1467.47021484375,49.3817265879668,20.5844411477153,34.7295951843262,0,0,0,20,298.252502441406,1,6,1,2.21542358398438,43.0107536315918,,,,,,,,,,,,,,,,
,3900589583.693,300.173553466797,-1582.05346679687,-6.65659486540685E-5,1.84559322840391E-6,1,0.499626677034896,40.0298881530762,2.00070948734628,55.9299997985363,-0.000334053176107247,-7.28729843426753E-5,0.25,-2.06790240093663E-6,-6.65459627089716E-5,-2.32434917701011E-6,300.173553466797,300.173553466797,-1584.53625488281,-1579.57067871094,48.5016128753128,20.5750984695642,34.7463226318359,0,0,0,20,298.250885009766,1,6,1,2.22793579101562,40.0782012939453,,,,,,,,,,,,,,,,
,3900589595.2375,300.165390014648,-1697.27044677734,-6.92571429868953E-5,2.37912468825964E-6,1,0.499626677034896,40.0298881530762,2.00077038007634,55.9299997985363,-0.000346596713709329,-8.10536340416072E-5,0.25,-3.18805798686082E-6,-6.92323655045231E-5,-3.45469330342258E-6,300.161163330078,300.161163330078,-1699.29626464844,-1695.24462890625,47.3166640401589,20.5742652218472,34.7579193115234,0,0,0,20,298.244873046875,1,6,1,2.215576171875,41.055721282959,,,,,,,,,,,,,,,,
,3900589606.6905,300.164535522461,-1811.78521728516,-7.66229571274019E-5,1.50171228751408E-6,1,0.499626677034896,40.0298881530762,2.00066281483424,55.9399984776974,-0.000384454696741153,-8.42024550019808E-5,0.25,-2.444008908941E-6,-7.6599725381532E-5,-2.73919633449413E-6,300.1669921875,300.1669921875,-1814.25048828125,-1809.31994628906,50.0492373433899,20.57776447348,34.7843551635742,0,0,0,20,298.243804931641,1,6,1,2.22274780273438,41.5444793701172,,,,,,,,,,,,,,,,
,3900589618.157,300.160919189453,-1926.68865966797,-7.88686849724557E-5,2.69412323361734E-6,1,0.499626677034896,40.0298881530762,2.00081909770843,55.9299997985363,-0.000394801496619496,-9.17958809391693E-5,0.25,-3.52973679254919E-6,-7.88408677757825E-5,-3.8333958132974E-6,300.160919189453,300.160919189453,-1929.18371582031,-1924.19360351562,48.996383727986,20.5803997607216,34.7827377319336,0,0,0,20,298.247619628906,1,6,1,2.2125244140625,41.055721282959,,,,,,,,,,,,,,,,
,3900589629.6535,300.161468505859,-2041.70416259766,-8.42444078790202E-5,2.71724621263509E-6,1,0.499626677034896,40.0298881530762,2.00070069997721,55.9299997985363,-0.000422294208557203,-9.47797030087779E-5,0.25,-3.12300158220824E-6,-8.42171912030049E-5,-3.44747167757361E-6,300.157501220703,300.157501220703,-2044.16870117187,-2039.23962402344,48.6047878398513,20.580081149103,34.7954177856445,0,0,0,20,298.253967285156,1,6,1,2.22213745117187,40.0782012939453,,,,,,,,,,,,,,,,
,3900589641.147,300.158355712891,-2156.77722167969,-8.75428412790459E-5,2.48746255421468E-6,1,0.499626677034896,40.0298881530762,2.000649240185,55.9299997985363,-0.000439780441706828,-9.33056742957401E-5,0.25,-2.218503692011E-6,-8.75185282619741E-5,-2.55586470041506E-6,300.160308837891,300.160308837891,-2159.16235351562,-2154.39208984375,48.4484621360051,20.5709873970806,34.8102531433105,0,0,0,20,298.251800537109,1,6,1,2.20977783203125,43.0107536315918,,,,,,,,,,,,,,,,
,3900589652.642,300.156799316406,-2271.12133789062,-9.39277203058119E-5,2.09276063242711E-6,1,0.499626677034896,40.0298881530762,2.00077819551304,55.9399984776974,-0.000470994907436673,-0.00010490791420581,0.25,-3.3294111230862E-6,-9.38979765034323E-5,-3.69120639998396E-6,300.157440185547,300.157440185547,-2273.11938476562,-2269.12329101562,48.8947720204859,20.5798732506265,34.8194236755371,0,0,0,20,298.24169921875,1,6,1,2.23709106445313,42.0332374572754,,,,,,,,,,,,,,,,
,3900589664.1495,300.159881591797,-2386.06469726562,-9.80632139727955E-5,2.46333650987022E-6,1,0.499626677034896,40.0298881530762,2.00093918845759,55.9500008821487,-0.000491054007007704,-0.000113391413820076,0.25,-4.23986182272826E-6,-9.80292055712081E-5,-4.61744128551926E-6,300.160247802734,300.160247802734,-2388.06469726562,-2384.06469726562,48.1905247246589,20.5786236355892,34.819694519043,0,0,0,20,298.237396240234,1,6,1,2.22122192382813,41.5444793701172,,,,,,,,,,,,,,,,
,3900589675.635,300.155715942383,-2501.19445800781,-0.000104068137333439,1.89346728373654E-6,1,0.499626677034896,40.0298881530762,2.00045859515352,55.9299997985363,-0.000525025612818832,-9.86545735028427E-5,0.25,-2.09274782961312E-7,-0.000104048611071345,-6.10751398571118E-7,300.157928466797,300.157928466797,-2503.14721679687,-2499.24169921875,48.952612530909,20.5756679128289,34.8356094360352,0,0,0,20,298.242156982422,1,6,1,2.22061157226562,41.5444793701172,,,,,,,,,,,,,,,,
,3900589687.114,300.155090332031,-2615.765625,-0.00010890399190472,2.28619655035569E-6,1,0.499626677034896,40.0298881530762,2.00089608529051,55.9299997985363,-0.00054599666908706,-0.000122326329704127,0.25,-3.99585952543054E-6,-0.000108868988714063,-4.41531076441903E-6,300.156219482422,300.156219482422,-2618.28271484375,-2613.24853515625,48.3343443721974,20.578822687196,34.8515243530273,0,0,0,20,298.247039794922,1,6,1,2.222900390625,41.5444793701172,,,,,,,,,,,,,,,,
,3900589698.5975,300.150146484375,-2730.69079589844,-0.000113600946507536,2.63916446179312E-6,1,0.499626677034896,40.0298881530762,2.00043598865705,55.9299997985363,-0.000571081823814369,-0.000118618851008623,0.25,-2.39385707105085E-6,-0.000113571295212256,-2.83172382696675E-6,300.150146484375,300.150146484375,-2733.18823242187,-2728.193359375,49.2324355407937,20.5728256411239,34.859619140625,0,0,0,20,298.238708496094,1,6,1,2.21633911132813,42.5219955444336,,,,,,,,,,,,,,,,
touchdown = 49.8399995267391 mm,3900589734.4305,300.148651123047,-3000.30322265625,-0.000122912069965506,1.95607441738871E-6,1,0.499626677034896,40.0298881530762,1.98746684104843,55.8499991893768,-0.000614919698969155,-0.00012253603675734,0.25,-1.59395660164265E-6,-0.000122883837503123,-2.06788608808694E-6,300.148651123047,300.148651123047,-3000.30322265625,-3000.30322265625,48.3585748562936,20.5800815119067,34.8895606994629,0,0,0,20,298.245025634766,1,4,1,2.21267700195313,38.6119270324707,,,,,,,,,,,,,,,,
,3900589752.0665,300.150390625,-2895.92419433594,-0.000119645633198396,2.40200252343876E-6,1,0.499626677034896,40.0298881530762,1.98726978669593,55.8499991893768,-0.000595996989320132,-0.000132846468989721,0.25,-4.25940924336134E-6,-0.000119607697728057,-4.72025708576084E-6,300.150390625,300.150390625,-2898.421875,-2893.42651367188,49.0206142120821,20.5766344549973,34.9008903503418,0,0,0,20,298.244110107422,1,6,1,2.18093872070313,43.0107536315918,,,,,,,,,,,,,,,,
,3900589763.557,300.143920898438,-2781.1748046875,-0.000115961202905335,2.70885152592772E-6,1,0.499626677034896,40.0298881530762,1.98698221875042,55.8499991893768,-0.000578453842736603,-0.000123939537133498,0.25,-3.17129769717022E-6,-0.000115928147931192,-3.61814130857967E-6,300.145690917969,300.145690917969,-2783.80541992187,-2778.54418945313,48.7775277426013,20.5712897269194,34.8995399475098,0,0,0,20,298.237213134766,1,6,1,2.19696044921875,40.5669593811035,,,,,,,,,,,,,,,,
,3900589775.044,300.147125244141,-2666.48913574219,-0.000112406026322719,1.73613856107338E-6,1,0.499626677034896,40.0298881530762,1.98718605080681,55.8600015938282,-0.000561282522461005,-0.00011742242456725,0.25,-2.52976842872227E-6,-0.000112376074551713,-2.96300769578474E-6,300.145629882812,300.145629882812,-2668.470703125,-2664.50756835938,48.0920395312359,20.5735574474428,34.9132995605469,0,0,0,20,298.236206054687,1,6,1,2.21221923828125,43.0107536315918,,,,,,,,,,,,,,,,
,3900589786.5425,300.143051147461,-2551.15734863281,-0.000105324465556276,2.40812859895604E-6,1,0.499626677034896,40.0298881530762,1.98712867155629,55.8499991893768,-0.000525527864107895,-0.000112062562098472,0.25,-2.77739190415725E-6,-0.000105294841883359,-3.18327392222464E-6,300.139678955078,300.139678955078,-2553.6689453125,-2548.64575195313,48.8760129360244,20.576583216403,34.9230079650879,0,0,0,20,298.229431152344,1,6,1,2.21221923828125,41.5444793701172,,,,,,,,,,,,,,,,
,3900589798.047,300.140487670898,-2436.15295410156,-9.93854052876394E-5,2.8258571885736E-6,1,0.499626677034896,40.0298881530762,1.98739450703005,55.8600015938282,-0.000496907317755428,-0.000100653370082845,0.25,-1.60300041862366E-6,-9.93613857601856E-5,-1.98618496208922E-6,300.140594482422,300.140594482422,-2438.658203125,-2433.64770507813,48.1694207546397,20.579748526005,34.9262466430664,0,0,0,20,298.232604980469,1,6,1,2.21420288085938,41.5444793701172,,,,,,,,,,,,,,,,
,3900589809.523,300.148162841797,-2321.48291015625,-9.55912938416389E-5,2.06276615870877E-6,1,0.499626677034896,40.0298881530762,1.98702054397734,55.8499991893768,-0.000477535496936115,-9.84849091681294E-5,0.25,-1.87923598452346E-6,-9.55668687735672E-5,-2.24772257978819E-6,300.148162841797,300.148162841797,-2323.49536132813,-2319.47045898438,48.3890583685436,20.5694504394484,34.9311027526855,0,0,0,20,298.230194091797,1,6,1,2.2113037109375,42.5219955444336,,,,,,,,,,,,,,,,
,3900589821.0065,300.138946533203,-2206.56811523438,-9.19979560954919E-5,2.2383000482609E-6,1,0.499626677034896,40.0298881530762,1.98711445529637,55.8600015938282,-0.000458482795863081,-0.000100831064021914,0.25,-3.01394530240268E-6,-9.19698214487909E-5,-3.36837998490654E-6,300.138946533203,300.138946533203,-2208.552734375,-2204.58349609375,48.8861741067744,20.5691722199394,34.9362258911133,0,0,0,20,298.216491699219,1,6,1,2.2076416015625,42.0332374572754,,,,,,,,,,,,,,,,
,3900589832.518,300.143341064453,-2091.56689453125,-8.59268373009898E-5,1.97574686181528E-6,1,0.499626677034896,40.0298881530762,1.98711016657232,55.8499991893768,-0.000428499927823244,-9.27010673358782E-5,0.25,-2.52073375271009E-6,-8.59016842850774E-5,-2.85182763237926E-6,300.143341064453,300.143341064453,-2093.57373046875,-2089.56005859375,48.7626768007359,20.5664651757261,34.9356880187988,0,0,0,20,298.216491699219,1,6,1,2.21969604492187,41.5444793701172,,,,,,,,,,,,,,,,
,3900589844.006,300.135604858398,-1976.57232666016,-8.2135699637298E-5,2.4383708151016E-6,1,0.499626677034896,40.0298881530762,1.98723453587365,55.8499991893768,-0.000409351800551897,-9.00561165505029E-5,0.25,-2.69660717073766E-6,-8.2110565801269E-5,-3.01305399443028E-6,300.135681152344,300.135681152344,-1978.54858398438,-1974.59606933594,48.6735711495436,20.571511053527,34.9532203674316,0,0,0,20,298.222595214844,1,6,1,2.20626831054687,42.5219955444336,,,,,,,,,,,,,,,,
,3900589855.493,300.1328125,-1861.56640625,-7.79198852765598E-5,2.68076479442156E-6,1,0.499626677034896,40.0298881530762,1.98755362830601,55.8600015938282,-0.000387293717337911,-9.14088514408664E-5,0.25,-3.74691757695378E-6,-7.78914603026323E-5,-4.04691451666399E-6,300.1328125,300.1328125,-1863.55529785156,-1859.57751464844,48.6688813784282,20.5723624616013,34.9551086425781,0,0,0,20,298.218994140625,1,6,1,2.19009399414062,43.0107536315918,,,,,,,,,,,,,,,,
,3900589866.992,300.135406494141,-1747.28356933594,-7.09017229690699E-5,2.14732993340558E-6,1,0.499626677034896,40.0298881530762,1.9872113463155,55.8499991893768,-0.000354543412452313,-7.13660413988078E-5,0.25,-1.05705178603758E-6,-7.08849300369842E-5,-1.330448905115E-6,300.131164550781,300.131164550781,-1749.68371582031,-1744.88342285156,48.6548120650821,20.5680761744567,34.9656295776367,0,0,0,20,298.211395263672,1,6,1,2.19757080078125,42.0332374572754,,,,,,,,,,,,,,,,
,3900589878.4745,300.139556884766,-1632.59979248047,-6.81005650455644E-5,1.99302611976958E-6,1,0.499626677034896,40.0298881530762,1.98738123956798,55.8499991893768,-0.000341897997368091,-6.13763337782076E-5,0.25,4.15652167704137E-7,-6.80899490392068E-5,1.5280226206486E-7,300.14013671875,300.14013671875,-1634.50988769531,-1630.68969726562,47.1196936533127,20.5737230612164,34.973991394043,0,0,0,20,298.210693359375,1,6,1,2.20291137695313,40.5669593811035,,,,,,,,,,,,,,,,
,3900589889.9695,300.133453369141,-1517.44622802734,-6.28470143397422E-5,2.33696957086566E-6,1,0.499626677034896,40.0298881530762,1.98731412942135,55.8600015938282,-0.000312442633220404,-7.31588909751065E-5,0.25,-2.91060837350805E-6,-6.28245164059849E-5,-3.15259785351216E-6,300.128356933594,300.128356933594,-1520.01733398438,-1514.87512207031,47.4518857739858,20.5709838782559,34.9645500183105,0,0,0,20,298.214111328125,1,6,1,2.203369140625,42.5219955444336,,,,,,,,,,,,,,,,
,3900589901.4515,300.13427734375,-1403.02624511719,-5.92493898534327E-5,1.87137213704055E-6,1,0.499626677034896,40.0298881530762,1.98721938373253,55.8600015938282,-0.000295619780767794,-6.31755081905341E-5,0.25,-1.58886736471119E-6,-5.92326356263994E-5,-1.81721212410104E-6,300.132476806641,300.132476806641,-1405.00036621094,-1401.05212402344,48.1584779553705,20.5748854732903,34.9712944030762,0,0,0,20,298.213623046875,1,6,1,2.20672607421875,42.0332374572754,,,,,,,,,,,,,,,,
,3900589912.959,300.124908447266,-1287.43756103516,-5.4516638537233E-5,2.33756507838703E-6,1,0.499626677034896,40.0298881530762,1.98747135705482,55.8600015938282,-0.000271620191696072,-6.03942196353124E-5,0.25,-1.91216646011065E-6,-5.44994991461804E-5,-2.12220035082201E-6,300.124633789063,300.124633789063,-1289.98205566406,-1284.89306640625,48.5008312467936,20.579274591339,34.9761505126953,0,0,0,20,298.214904785156,1,6,1,2.21115112304687,41.055721282959,,,,,,,,,,,,,,,,
,3900589924.471,300.128112792969,-1172.48791503906,-4.60164299934511E-5,2.40783371130659E-6,1,0.499626677034896,40.0298881530762,1.98742366446411,55.8499991893768,-0.000229227749178775,-5.11710576785997E-5,0.25,-1.65284210272684E-6,-4.6001808990043E-5,-1.83011935364156E-6,300.128112792969,300.128112792969,-1174.01794433594,-1170.95788574219,48.1967777528128,20.5752113590513,34.9917945861816,0,0,0,20,298.217590332031,1,6,1,2.20596313476562,43.0107536315918,,,,,,,,,,,,,,,,
,3900589935.922,300.126541137695,-1057.49084472656,-4.28231517579894E-5,1.79185016266124E-6,1,0.499626677034896,40.0298881530762,1.98731578232911,55.8499991893768,-0.000215458575838292,-3.6051833681607E-5,0.25,7.6825063023112E-7,-4.28184473651094E-5,6.02860255506012E-7,300.123260498047,300.123260498047,-1060.03100585938,-1054.95068359375,49.0112346698513,20.5737614557109,34.9988098144531,0,0,0,20,298.223175048828,1,6,1,2.19818115234375,41.5444793701172,,,,,,,,,,,,,,,,
,3900589947.4295,300.125106811523,-943.612670898438,-3.85782842694933E-5,2.54470290854281E-6,1,0.499626677034896,40.0298881530762,1.98736251365464,55.8600015938282,-0.000191978682666629,-4.39246897852535E-5,0.25,-1.5903192132442E-6,-3.85652398419354E-5,-1.73890822579906E-6,300.126434326172,300.126434326172,-946.088256835938,-941.137084960937,49.1878827151975,20.5714533405812,34.9971923828125,0,0,0,20,298.218566894531,1,6,1,2.20428466796875,43.0107536315918,,,,,,,,,,,,,,,,
,3900589958.9175,300.125793457031,-828.523254394531,-3.43898547255537E-5,2.02800102981585E-6,1,0.499626677034896,40.0298881530762,1.98751061172079,55.8600015938282,-0.000171203849731747,-3.88583051707629E-5,0.25,-1.35777210328023E-6,-3.43784568833595E-5,-1.490239973419E-6,300.125793457031,300.125793457031,-830.983642578125,-826.062866210937,48.1959961242936,20.5729214960304,34.9950332641602,0,0,0,20,298.209045410156,1,6,1,2.21954345703125,42.5219955444336,,,,,,,,,,,,,,,,
,3900589970.45,300.128952026367,-712.902954101562,-2.76180193721144E-5,2.51759517102415E-6,1,0.499626677034896,40.0298881530762,1.98736242059962,55.8600015938282,-0.00013737589357051,-3.17724381235995E-5,0.25,-1.20370155587526E-6,-2.76084262619492E-5,-1.31006355590176E-6,300.127319335937,300.127319335937,-714.906799316406,-710.899108886719,48.0967293023512,20.5726492255764,34.9931449890137,0,0,0,20,298.210601806641,1,6,1,2.21023559570313,42.0332374572754,,,,,,,,,,,,,,,,
,3900589981.889,300.130218505859,-598.526245117187,-2.46090086405014E-5,2.530725630235E-6,1,0.499626677034896,40.0298881530762,1.9874162988715,55.8499991893768,-0.000121581149195334,-3.27820629424583E-5,0.25,-1.96400647700327E-6,-2.45970196943332E-5,-2.05862048872679E-6,300.130218505859,300.130218505859,-601.05322265625,-595.999267578125,48.4226683948705,20.5697261183548,35.0141868591309,0,0,0,20,298.212707519531,1,6,1,2.20687866210938,41.055721282959,,,,,,,,,,,,,,,,
,3900589993.399,300.120162963867,-482.910247802734,-1.7718793625458E-5,2.76061736277252E-6,1,0.499626677034896,40.0298881530762,1.986733492218,55.8499991893768,-8.78707184068055E-5,-2.16581667154072E-5,0.25,-1.02763895952225E-6,-1.77116575795468E-5,-1.09583487176178E-6,300.120788574219,300.120788574219,-484.882385253906,-480.938110351562,49.3637491320245,20.5618808736142,35.0211982727051,0,0,0,20,298.213531494141,1,6,1,2.20474243164062,39.1006851196289,,,,,,,,,,,,,,,,
,3900590004.8955,300.125823974609,-368.530715942383,-1.50025743096065E-5,2.14782796579564E-6,1,0.499626677034896,40.0298881530762,1.98746698033012,55.8600015938282,-7.54426519215935E-5,-1.28801514749554E-5,0.25,2.19520181822269E-7,-1.50007348280417E-5,1.61584450498689E-7,300.124816894531,300.124816894531,-371.049987792969,-366.011444091797,47.757502525005,20.5687777200707,35.0368461608887,0,0,0,20,298.20703125,1,6,1,2.19711303710938,41.055721282959,,,,,,,,,,,,,,,,
,3900590016.3895,300.122100830078,-253.005905151367,-8.19596406855398E-6,2.16316963848041E-6,1,0.499626677034896,40.0298881530762,1.98740046693226,55.8600015938282,-4.12550198518942E-5,-6.81158870471738E-6,0.25,1.64724124123694E-7,-8.1951328884115E-6,1.33064985899226E-7,300.124572753906,300.124572753906,-255.014923095703,-250.996887207031,48.9916939568706,20.5717474864705,35.0433197021484,0,0,0,20,298.207824707031,1,6,1,2.21359252929687,42.0332374572754,,,,,,,,,,,,,,,,
,3900590027.862,300.123123168945,-138.550483703613,-4.38482912459555E-6,1.75706815066022E-6,1,0.499626677034896,40.0298881530762,1.98742422214942,55.8600015938282,-2.14303238340179E-5,-7.0953942385753E-6,0.25,-6.00053482592968E-7,-4.38172850278211E-6,-6.16867894806885E-7,300.121673583984,300.121673583984,-140.996154785156,-136.10481262207,48.4367377082167,20.5751759569206,35.056266784668,0,0,0,20,298.202697753906,1,6,1,2.21481323242187,41.5444793701172,,,,,,,,,,,,,,,,
,3900590039.3645,300.117523193359,-23.6057329177856,-1.45828485637041E-6,2.27713195940878E-6,1,0.499626677034896,40.0298881530762,1.98737886364409,55.8499991893768,-5.30425869560294E-6,-1.21688345608919E-5,0.25,-2.15560152810701E-6,-1.44970498110835E-6,-2.16084391979996E-6,300.117370605469,300.117370605469,-26.1311931610107,-21.0802726745605,48.5313147590436,20.5656270973538,35.0570755004883,0,0,0,20,298.207000732422,1,6,1,2.1905517578125,41.5444793701172,,,,,,,,,,,,,,,,
,3900590050.8455,300.121307373047,90.9725303649902,8.71160423869833E-6,2.06066428691322E-6,1,0.499626677034896,40.0298881530762,1.9876400874724,55.8499991893768,4.43714028040171E-5,4.46566427133501E-6,0.25,-7.28443037597688E-7,8.71285646148159E-6,-6.94692771492319E-7,300.119537353516,300.119537353516,89.0226058959961,92.9224548339844,49.6693658830437,20.5667877711104,35.053840637207,0,0,0,20,298.204650878906,1,6,1,2.2076416015625,41.055721282959,,,,,,,,,,,,,,,,
,3900590062.3485,300.121490478516,206.402526855469,9.87271642460335E-6,2.05116094845081E-6,1,0.499626677034896,40.0298881530762,1.98759176725383,55.8499991893768,4.94778384487806E-5,9.40003552192017E-6,0.25,3.96755218949573E-8,9.87079649366215E-6,7.77691199556122E-8,300.122863769531,300.122863769531,203.913848876953,208.891204833984,48.9565206735052,20.5730619798251,35.061393737793,0,0,0,20,298.204711914063,1,6,1,2.21084594726562,42.5219955444336,,,,,,,,,,,,,,,,
,3900590073.832,300.119323730469,320.902206420898,1.50812066376472E-5,2.12949823697508E-6,1,0.499626677034896,40.0298881530762,1.98758472639299,55.8600015938282,7.7184622878013E-5,5.72561579563878E-6,0.25,-1.66082370092577E-6,1.50849181118782E-5,-1.60232509150654E-6,300.118286132812,300.118286132812,318.918487548828,322.885925292969,49.1738134018514,20.5670929404497,35.0897178649902,0,0,0,20,298.206390380859,1,6,1,2.20932006835938,42.0332374572754,,,,,,,,,,,,,,,,
,3900590085.3155,300.116226196289,435.892807006836,1.77534769732237E-5,1.42488220786711E-6,1,0.499626677034896,40.0298881530762,1.98737298371884,55.8499991893768,8.92556251702304E-5,1.53286869194863E-5,0.25,-2.42325419516456E-7,1.77512376800557E-5,-1.73767247709053E-7,300.119598388672,300.119598388672,433.860900878906,437.924713134766,48.9979469850244,20.5669167269528,35.1053619384766,0,0,0,20,298.209564208984,1,6,1,2.19818115234375,41.5444793701172,,,,,,,,,,,,,,,,
,3900590096.8265,300.114028930664,550.850433349609,2.11470161331194E-5,2.83730916377203E-6,1,0.499626677034896,40.0298881530762,1.9873439153489,55.8499991893768,0.00010657623802893,1.68533944807019E-5,0.25,-5.6883721183275E-7,2.11454314732705E-5,-4.87123938849535E-7,300.112243652344,300.112243652344,548.919189453125,552.781677246094,48.2342959217359,20.5588215632754,35.1088676452637,0,0,0,20,298.201324462891,1,6,1,2.19390869140625,43.0107536315918,,,,,,,,,,,,,,,,
,3900590108.299,300.111877441406,665.328399658203,3.02012672824187E-5,2.37946428345921E-6,1,0.499626677034896,40.0298881530762,1.98732366488289,55.8700002729893,0.000153315574648043,1.80987265837706E-5,0.25,-2.00296559800097E-6,3.02036007650963E-5,-1.88605312982433E-6,300.115875244141,300.115875244141,662.823425292969,667.833374023437,47.2439725878704,20.5683220775257,35.1142654418945,0,0,0,20,298.195495605469,1,6,1,2.1990966796875,41.5444793701172,,,,,,,,,,,,,,,,
,3900590119.7945,300.111968994141,780.246887207031,3.31363425451819E-5,2.10386274449873E-6,1,0.499626677034896,40.0298881530762,1.98754761523276,55.8499991893768,0.000164687411105245,3.89445677668209E-5,0.25,1.60775432239863E-6,3.31242168845397E-5,1.73534806707345E-6,300.107513427734,300.107513427734,777.735290527344,782.758483886719,47.4643918302935,20.5663546876341,35.1253242492676,0,0,0,20,298.194152832031,1,6,1,2.1966552734375,43.0107536315918,,,,,,,,,,,,,,,,
,3900590131.29,300.106872558594,895.497131347656,3.97519206105845E-5,2.51733810909969E-6,1,0.499626677034896,40.0298881530762,1.98781569723351,55.8499991893768,0.00020007805987227,3.33514041559233E-5,0.25,-7.37696398910117E-7,3.97476702768573E-5,-5.841503556782E-7,300.106872558594,300.106872558594,893.001647949219,897.992614746094,49.1190994055052,20.5789247127288,35.1331481933594,0,0,0,20,298.198333740234,1,6,1,2.22198486328125,41.055721282959,,,,,,,,,,,,,,,,
,3900590142.8335,300.10498046875,1010.94540405273,4.26729592510307E-5,3.40191519695365E-6,1,0.499626677034896,40.0298881530762,1.98741708721955,55.8499991893768,0.000212876217920835,4.58154020426648E-5,0.25,1.20619840486725E-6,4.2660687669099E-5,1.37067085310491E-6,300.10498046875,300.10498046875,1008.93127441406,1012.95953369141,49.5106952936399,20.5630461588693,35.138542175293,0,0,0,20,298.196411132812,1,6,1,2.20855712890625,41.055721282959,,,,,,,,,,,,,,,,
,3900590154.2705,300.110382080078,1125.40844726562,4.8296296330044E-5,1.53068641416281E-6,1,0.499626677034896,40.0298881530762,1.98759544965249,55.8499991893768,0.00024273457850092,4.22512504948181E-5,0.25,-5.50197364018532E-7,4.82897922852074E-5,-3.63714335673298E-7,300.109802246094,300.109802246094,1122.92004394531,1127.89685058594,49.1777215444475,20.5754960697829,35.1380004882812,0,0,0,20,298.197296142578,1,6,1,2.21389770507813,42.5219955444336,,,,,,,,,,,,,,,,
,3900590165.7725,300.105194091797,1240.38647460938,5.1109859335205E-5,2.26110487467025E-6,1,0.499626677034896,40.0298881530762,1.98746466455664,55.8600015938282,0.000258392917477892,3.64550210332986E-5,0.25,-2.22826653117787E-6,5.11093363218947E-5,-2.03062313925225E-6,300.105194091797,300.105194091797,1237.92590332031,1242.84704589844,48.9361983320052,20.5644714859637,35.1382713317871,0,0,0,20,298.195526123047,1,6,1,2.2027587890625,43.49951171875,,,,,,,,,,,,,,,,
,3900590177.2425,300.10595703125,1355.32305908203,5.84310582062558E-5,2.24370015887165E-6,1,0.499626677034896,40.0298881530762,1.98710919276326,55.8400005102158,0.000293720132440453,5.04666501039991E-5,0.25,-7.93028974329899E-7,5.8423688371528E-5,-5.67389519729946E-7,300.102935791016,300.102935791016,1352.78588867188,1357.86022949219,48.4031276818897,20.5669089172672,35.1541862487793,0,0,0,20,298.199951171875,1,6,1,2.198486328125,41.5444793701172,,,,,,,,,,,,,,,,
,3900590188.7525,300.106872558594,1469.82086181641,6.22397271778884E-5,2.56833518116125E-6,1,0.499626677034896,40.0298881530762,1.98737267889099,55.8499991893768,0.000311028935477206,6.38635994256334E-5,0.25,1.16942364667044E-6,6.22241025450566E-5,1.40940881442417E-6,300.108917236328,300.108917236328,1467.83337402344,1471.80834960938,48.4015644248513,20.5691335076655,35.1606597900391,0,0,0,20,298.195526123047,1,6,1,2.21908569335938,43.0107536315918,,,,,,,,,,,,,,,,
,3900590200.2195,300.101135253906,1584.70611572266,6.82649953944378E-5,1.76662576863802E-6,1,0.499626677034896,40.0298881530762,1.98758531778423,55.8499991893768,0.000343471208674253,5.76934252817835E-5,0.25,-1.18181813353169E-6,6.82573800876765E-5,-9.1815653837629E-7,300.102264404297,300.102264404297,1582.60485839844,1586.80737304687,49.8147487876207,20.569681517021,35.1657867431641,0,0,0,20,298.189971923828,1,6,1,2.21282958984375,42.5219955444336,,,,,,,,,,,,,,,,
,3900590211.7395,300.101654052734,1700.07977294922,7.17273464709622E-5,1.9804086768598E-6,1,0.499626677034896,40.0298881530762,1.98757503052552,55.8499991893768,0.000359592163962248,6.76034842935606E-5,0.25,1.50826868359992E-7,7.17139697363221E-5,4.27610381692158E-7,300.101654052734,300.101654052734,1697.66796875,1702.49157714844,49.626376314486,20.5699965143446,35.1773872375488,0,0,0,20,298.192443847656,1,6,1,2.2039794921875,41.5444793701172,,,,,,,,,,,,,,,,
,3900590223.214,300.108963012695,1814.50866699219,7.59683300269517E-5,2.67872556630623E-6,1,0.499626677034896,40.0298881530762,1.98737670079749,55.8499991893768,0.00038110121224321,7.00615421186102E-5,0.25,-1.45766541400697E-7,7.59553260647968E-5,1.47426237317855E-7,300.108856201172,300.108856201172,1812.52136230469,1816.49597167969,48.9236922756975,20.5655880899754,35.1717224121094,0,0,0,20,298.197875976562,1,6,1,2.215576171875,43.49951171875,,,,,,,,,,,,,,,,
,3900590234.711,300.103408813477,1929.40704345703,8.23969567110804E-5,2.39099472187213E-6,1,0.499626677034896,40.0298881530762,1.98753049710771,55.8499991893768,0.000413091424853071,7.75604840586161E-5,0.25,1.53832334452765E-7,8.23816615091999E-5,4.71784989832007E-7,300.105102539063,300.105102539063,1927.43701171875,1931.37707519531,48.5641431568513,20.5694707306312,35.169563293457,0,0,0,20,298.189270019531,1,6,1,2.21221923828125,43.0107536315918,,,,,,,,,,,,,,,,
,3900590246.2035,300.103256225586,2043.95043945313,8.69274273382047E-5,1.92515187377159E-6,1,0.499626677034896,40.0298881530762,1.98742139802857,55.8499991893768,0.000434479041781343,8.8828908314202E-5,0.25,1.55977761488667E-6,8.69058986943151E-5,1.89496097815012E-6,300.106506347656,300.106506347656,2041.47290039062,2046.42797851562,48.7853440277936,20.5657157865243,35.1652488708496,0,0,0,20,298.189300537109,1,6,1,2.20550537109375,43.49951171875,,,,,,,,,,,,,,,,
,3900590257.6815,300.104858398438,2158.87390136719,9.07623908260381E-5,2.30647967220884E-6,1,0.499626677034896,40.0298881530762,1.98761881071304,55.8600015938282,0.000455772786544433,8.15522445463194E-5,0.25,-6.05425713007758E-7,9.07485298295204E-5,-2.55061179320306E-7,300.104858398438,300.104858398438,2156.32080078125,2161.42700195313,48.9533941594283,20.5630008045405,35.1665954589844,0,0,0,20,298.191467285156,1,6,1,2.19757080078125,42.0332374572754,,,,,,,,,,,,,,,,
,3900590269.192,300.102157592773,2274.28540039062,9.63920171739243E-5,1.80194238322886E-6,1,0.499626677034896,40.0298881530762,1.98773222154596,55.8600015938282,0.000485025951658281,8.14681257399687E-5,0.25,-1.66922243024973E-6,9.63812642927164E-5,-1.29694181138722E-6,300.106201171875,300.106201171875,2272.30102539062,2276.26977539062,48.0693723041782,20.568681510288,35.177116394043,0,0,0,20,298.186462402344,1,6,1,2.1990966796875,42.5219955444336,,,,,,,,,,,,,,,,
,3900590280.678,300.101455688477,2388.73986816406,9.94035539154804E-5,2.48805929797167E-6,1,0.499626677034896,40.0298881530762,1.98782359219495,55.8499991893768,0.00049780106342431,9.69366260005003E-5,0.25,8.54335192654204E-7,9.9382527474198E-5,1.23778574046438E-6,300.099700927734,300.099700927734,2386.232421875,2391.24731445313,49.0253039831975,20.5591498561046,35.177116394043,0,0,0,20,298.186737060547,1,6,1,2.21405029296875,43.0107536315918,,,,,,,,,,,,,,,,
,3900590292.1575,300.09635925293,2503.53088378906,0.000106893437788209,2.7425199787455E-6,1,0.499626677034896,40.0298881530762,1.9873960064438,55.8600015938282,0.000536487358154328,9.72775587574743E-5,0.25,-4.65441608163372E-7,0.000106876184036351,-5.28465162493078E-8,300.096435546875,300.096435546875,2501.564453125,2505.49731445313,48.6297999524667,20.5633438918517,35.1749572753906,0,0,0,20,298.185974121094,1,6,1,2.2015380859375,43.0107536315918,,,,,,,,,,,,,,,,
,3900590303.6575,300.092803955078,2618.47644042969,0.0001100533832081,2.39218325436265E-6,1,0.499626677034896,40.0298881530762,1.98747376480104,55.8499991893768,0.000550561870480735,0.000109876071833073,0.25,1.45877057821224E-6,0.000110028151749564,1.88322036355597E-6,300.094390869141,300.094390869141,2616.47924804687,2620.4736328125,49.3027821075244,20.5650924839859,35.1563453674316,0,0,0,20,298.187316894531,1,6,1,2.20870971679687,42.0332374572754,,,,,,,,,,,,,,,,
,3900590315.136,300.096664428711,2733.96997070313,0.000113309371980548,2.59274469718346E-6,1,0.499626677034896,40.0298881530762,1.98758646246228,55.8499991893768,0.000569802891103262,9.7413205907189E-5,0.25,-1.63243229774429E-6,0.000113295477864323,-1.19487642459279E-6,300.099914550781,300.099914550781,2731.4755859375,2736.46435546875,50.1383429945822,20.5630881957885,35.1477127075195,0,0,0,20,298.183319091797,1,6,1,2.20550537109375,43.0107536315918,,,,,,,,,,,,,,,,
touchdown = 49.770001322031 mm,3900590350.5845,300.087585449219,3000.3251953125,0.00012743065503627,1.81641012238934E-6,1,0.499626677034896,40.0298881530762,1.99969424215639,55.7800009846687,0.000641754620887034,0.000125587408583846,0.25,1.21357314292645E-6,0.000127403294392136,1.70512598316203E-6,300.087585449219,300.087585449219,3000.3251953125,3000.3251953125,47.8059634931974,20.57187881924,35.1692924499512,0,0,0,20,298.192596435547,1,4,1,2.22518920898438,40.5669593811035,,,,,,,,,,,,,,,,